(0.001) 
            SELECT name, type FROM sqlite_master
            WHERE type in ('table', 'view') AND NOT name='sqlite_sequence'
            ORDER BY name; args=None
(0.000) SELECT "django_migrations"."app", "django_migrations"."name" FROM "django_migrations"; args=()
(0.001) SELECT "auth_user"."id", "auth_user"."password", "auth_user"."last_login", "auth_user"."is_superuser", "auth_user"."username", "auth_user"."first_name", "auth_user"."last_name", "auth_user"."email", "auth_user"."is_staff", "auth_user"."is_active", "auth_user"."date_joined" FROM "auth_user" WHERE "auth_user"."username" = 'goblinsly'; args=('goblinsly',)
(0.001) SELECT (1) AS "a" FROM "django_session" WHERE "django_session"."session_key" = 'u9txi8tulni35b6kgahgojrlgnedzvag' LIMIT 1; args=('u9txi8tulni35b6kgahgojrlgnedzvag',)
(0.000) BEGIN; args=None
(0.001) INSERT INTO "django_session" ("session_key", "session_data", "expire_date") SELECT 'u9txi8tulni35b6kgahgojrlgnedzvag', 'MTBhMmJhNjQ2ZWE4ZmY3Y2FhYTYzNDRiZjdkNDIxNDYzMzI5NzE4Nzp7fQ==', '2017-01-19 19:29:32.864225'; args=('u9txi8tulni35b6kgahgojrlgnedzvag', 'MTBhMmJhNjQ2ZWE4ZmY3Y2FhYTYzNDRiZjdkNDIxNDYzMzI5NzE4Nzp7fQ==', '2017-01-19 19:29:32.864225')
(0.000) BEGIN; args=None
(0.000) UPDATE "auth_user" SET "last_login" = '2017-01-05 19:29:32.873273' WHERE "auth_user"."id" = 32; args=('2017-01-05 19:29:32.873273', 32)
(0.000) BEGIN; args=None
(0.001) UPDATE "django_session" SET "session_data" = 'OThkMWU5MTQ4ZTEwMDc0ZjI1NWFmMmYxYzUxNmY3YTIwODlmMWVmZDp7Il9hdXRoX3VzZXJfaGFzaCI6ImJiMWM0NGNhMjUwOTQ3NzVmMjcwYjY1ODcxNjRlMTU0YjBlODBmODMiLCJfYXV0aF91c2VyX2lkIjoiMzIiLCJfYXV0aF91c2VyX2JhY2tlbmQiOiJkamFuZ28uY29udHJpYi5hdXRoLmJhY2tlbmRzLk1vZGVsQmFja2VuZCJ9', "expire_date" = '2017-01-19 19:29:32.891318' WHERE "django_session"."session_key" = 'u9txi8tulni35b6kgahgojrlgnedzvag'; args=('OThkMWU5MTQ4ZTEwMDc0ZjI1NWFmMmYxYzUxNmY3YTIwODlmMWVmZDp7Il9hdXRoX3VzZXJfaGFzaCI6ImJiMWM0NGNhMjUwOTQ3NzVmMjcwYjY1ODcxNjRlMTU0YjBlODBmODMiLCJfYXV0aF91c2VyX2lkIjoiMzIiLCJfYXV0aF91c2VyX2JhY2tlbmQiOiJkamFuZ28uY29udHJpYi5hdXRoLmJhY2tlbmRzLk1vZGVsQmFja2VuZCJ9', '2017-01-19 19:29:32.891318', 'u9txi8tulni35b6kgahgojrlgnedzvag')
"POST /kalkulator/ HTTP/1.1" 302 0
(0.000) SELECT "django_session"."session_key", "django_session"."session_data", "django_session"."expire_date" FROM "django_session" WHERE ("django_session"."expire_date" > '2017-01-05 19:29:32.905357' AND "django_session"."session_key" = 'u9txi8tulni35b6kgahgojrlgnedzvag'); args=('2017-01-05 19:29:32.905357', 'u9txi8tulni35b6kgahgojrlgnedzvag')
(0.000) SELECT "auth_user"."id", "auth_user"."password", "auth_user"."last_login", "auth_user"."is_superuser", "auth_user"."username", "auth_user"."first_name", "auth_user"."last_name", "auth_user"."email", "auth_user"."is_staff", "auth_user"."is_active", "auth_user"."date_joined" FROM "auth_user" WHERE "auth_user"."id" = 32; args=(32,)
(0.001) SELECT "kalkulator_racun"."id", "kalkulator_racun"."uporabnik_id", "kalkulator_racun"."ime", "kalkulator_racun"."stanje" FROM "kalkulator_racun"; args=()
(0.000) SELECT "auth_user"."id", "auth_user"."password", "auth_user"."last_login", "auth_user"."is_superuser", "auth_user"."username", "auth_user"."first_name", "auth_user"."last_name", "auth_user"."email", "auth_user"."is_staff", "auth_user"."is_active", "auth_user"."date_joined" FROM "auth_user" WHERE "auth_user"."id" = 36; args=(36,)
(0.000) SELECT "auth_user"."id", "auth_user"."password", "auth_user"."last_login", "auth_user"."is_superuser", "auth_user"."username", "auth_user"."first_name", "auth_user"."last_name", "auth_user"."email", "auth_user"."is_staff", "auth_user"."is_active", "auth_user"."date_joined" FROM "auth_user" WHERE "auth_user"."id" = 36; args=(36,)
Exception while resolving variable 'warning' in template 'kalkulator/stanje.html'.
Traceback (most recent call last):
  File "C:\Program Files (x86)\Python35-32\lib\site-packages\django\template\base.py", line 885, in _resolve_lookup
    current = current[bit]
  File "C:\Program Files (x86)\Python35-32\lib\site-packages\django\template\context.py", line 75, in __getitem__
    raise KeyError(key)
KeyError: 'warning'

During handling of the above exception, another exception occurred:

Traceback (most recent call last):
  File "C:\Program Files (x86)\Python35-32\lib\site-packages\django\template\base.py", line 891, in _resolve_lookup
    if isinstance(current, BaseContext) and getattr(type(current), bit):
AttributeError: type object 'RequestContext' has no attribute 'warning'

During handling of the above exception, another exception occurred:

Traceback (most recent call last):
  File "C:\Program Files (x86)\Python35-32\lib\site-packages\django\template\base.py", line 900, in _resolve_lookup
    current = current[int(bit)]
ValueError: invalid literal for int() with base 10: 'warning'

During handling of the above exception, another exception occurred:

Traceback (most recent call last):
  File "C:\Program Files (x86)\Python35-32\lib\site-packages\django\template\base.py", line 907, in _resolve_lookup
    (bit, current))  # missing attribute
django.template.base.VariableDoesNotExist: Failed lookup for key [warning] in '[{\'None\': None, \'True\': True, \'False\': False}, {\'messages\': <django.contrib.messages.storage.fallback.FallbackStorage object at 0x038C17B0>, \'csrf_token\': <SimpleLazyObject: \'xqNRrqoThIHZMAIijJMHzrHrNReckOEcSLxNzRbC6XrssNmKt72Ug7a3NMJhKOgM\'>, \'perms\': <django.contrib.auth.context_processors.PermWrapper object at 0x03F96D70>, \'DEFAULT_MESSAGE_LEVELS\': {\'DEBUG\': 10, \'WARNING\': 30, \'INFO\': 20, \'ERROR\': 40, \'SUCCESS\': 25}, \'request\': <WSGIRequest: GET \'/kalkulator/stanje.html\'>, \'user\': <SimpleLazyObject: <User: goblinsly>>}, {}, {\'racuni\': <QuerySet [<Racun: 1: transakcijski racun, 0.00€ >, <Racun: 1: 3, 0.00€ >]>}, {\'block\': <Block Node: main. Contents: [<TextNode: \'\\n\\t<div id="Stanje"> \\n\\t\\t\\t\\n\'>, <django.template.defaulttags.CsrfTokenNode object at 0x03F960D0>, <TextNode: \' \\t\\t\\t\\t\\t\\t\\t\\t\\t\\t\\t\\n\\t\\t\\t<label>Pr\'>, <For Node: for racun in racuni, tail_len: 3>, <TextNode: \'\\t\\t\\t\\t\\t\\t\\t\\t\\t\\t\\t\\t\\t\\t\\t\\t\\t\\t\\t\\t\\t\\t\\n\\t\\t\'>, <Block Node: izpisStanja. Contents: [<TextNode: \'\\n\\t\\t\\t\'>]>, <TextNode: \'\\n\\t\\t\\t\\t\\t\\t\\t\\n\\t\\t\\t\'>, <Variable Node: warning>, <TextNode: \'\\t\\t\\t\\t\\t\\t\\t\\t\\n\\t\\t\\t\\t\\t\\n\\t\\t</div>\\t\\t\'>, <django.template.defaulttags.CsrfTokenNode object at 0x03F7FA50>, <TextNode: \' \\t\\n\\t\\t\\t<label>Dodaj nov ra\'>, <django.template.defaulttags.CsrfTokenNode object at 0x03F96530>, <TextNode: \' \\t\\t\\t\\t\\t\\t\\t\\t\\t\\t\\t\\n\\t\\t\\t<label>Iz\'>, <For Node: for racun in racuni, tail_len: 3>, <TextNode: \'\\t\\t\\t\\t\\t\\t\\t\\t\\t\\t\\t\\t\\t\\t\\t\\t\\t\\t\\t\\t\\t\\t\\n\\t\\t\'>]>}]'
"GET /kalkulator/stanje.html HTTP/1.1" 200 2588
(0.001) SELECT "django_session"."session_key", "django_session"."session_data", "django_session"."expire_date" FROM "django_session" WHERE ("django_session"."expire_date" > '2017-01-05 19:29:51.578008' AND "django_session"."session_key" = 'u9txi8tulni35b6kgahgojrlgnedzvag'); args=('2017-01-05 19:29:51.578008', 'u9txi8tulni35b6kgahgojrlgnedzvag')
(0.000) SELECT "auth_user"."id", "auth_user"."password", "auth_user"."last_login", "auth_user"."is_superuser", "auth_user"."username", "auth_user"."first_name", "auth_user"."last_name", "auth_user"."email", "auth_user"."is_staff", "auth_user"."is_active", "auth_user"."date_joined" FROM "auth_user" WHERE "auth_user"."id" = 32; args=(32,)
(0.001) SELECT "kalkulator_racun"."id", "kalkulator_racun"."uporabnik_id", "kalkulator_racun"."ime", "kalkulator_racun"."stanje" FROM "kalkulator_racun" WHERE ("kalkulator_racun"."uporabnik_id" = 32 AND "kalkulator_racun"."ime" = 'Transakcijski Racun'); args=(32, 'Transakcijski Racun')
(0.000) BEGIN; args=None
(0.001) INSERT INTO "kalkulator_racun" ("uporabnik_id", "ime", "stanje") VALUES (32, 'Transakcijski Racun', '0.00'); args=[32, 'Transakcijski Racun', '0.00']
(0.000) SELECT "kalkulator_racun"."id", "kalkulator_racun"."uporabnik_id", "kalkulator_racun"."ime", "kalkulator_racun"."stanje" FROM "kalkulator_racun"; args=()
(0.000) SELECT "auth_user"."id", "auth_user"."password", "auth_user"."last_login", "auth_user"."is_superuser", "auth_user"."username", "auth_user"."first_name", "auth_user"."last_name", "auth_user"."email", "auth_user"."is_staff", "auth_user"."is_active", "auth_user"."date_joined" FROM "auth_user" WHERE "auth_user"."id" = 36; args=(36,)
(0.000) SELECT "auth_user"."id", "auth_user"."password", "auth_user"."last_login", "auth_user"."is_superuser", "auth_user"."username", "auth_user"."first_name", "auth_user"."last_name", "auth_user"."email", "auth_user"."is_staff", "auth_user"."is_active", "auth_user"."date_joined" FROM "auth_user" WHERE "auth_user"."id" = 36; args=(36,)
(0.000) SELECT "auth_user"."id", "auth_user"."password", "auth_user"."last_login", "auth_user"."is_superuser", "auth_user"."username", "auth_user"."first_name", "auth_user"."last_name", "auth_user"."email", "auth_user"."is_staff", "auth_user"."is_active", "auth_user"."date_joined" FROM "auth_user" WHERE "auth_user"."id" = 32; args=(32,)
Exception while resolving variable 'warning' in template 'kalkulator/stanje.html'.
Traceback (most recent call last):
  File "C:\Program Files (x86)\Python35-32\lib\site-packages\django\template\base.py", line 885, in _resolve_lookup
    current = current[bit]
  File "C:\Program Files (x86)\Python35-32\lib\site-packages\django\template\context.py", line 75, in __getitem__
    raise KeyError(key)
KeyError: 'warning'

During handling of the above exception, another exception occurred:

Traceback (most recent call last):
  File "C:\Program Files (x86)\Python35-32\lib\site-packages\django\template\base.py", line 891, in _resolve_lookup
    if isinstance(current, BaseContext) and getattr(type(current), bit):
AttributeError: type object 'RequestContext' has no attribute 'warning'

During handling of the above exception, another exception occurred:

Traceback (most recent call last):
  File "C:\Program Files (x86)\Python35-32\lib\site-packages\django\template\base.py", line 900, in _resolve_lookup
    current = current[int(bit)]
ValueError: invalid literal for int() with base 10: 'warning'

During handling of the above exception, another exception occurred:

Traceback (most recent call last):
  File "C:\Program Files (x86)\Python35-32\lib\site-packages\django\template\base.py", line 907, in _resolve_lookup
    (bit, current))  # missing attribute
django.template.base.VariableDoesNotExist: Failed lookup for key [warning] in '[{\'None\': None, \'True\': True, \'False\': False}, {\'messages\': <django.contrib.messages.storage.fallback.FallbackStorage object at 0x03F96470>, \'csrf_token\': <SimpleLazyObject: \'kXuKqXWdkGxi3w1DLdjDHPyONdAm6vPVFieGyoJW9VhLJJF5VBzQov1qN85rwvrv\'>, \'perms\': <django.contrib.auth.context_processors.PermWrapper object at 0x03F7F2D0>, \'DEFAULT_MESSAGE_LEVELS\': {\'DEBUG\': 10, \'WARNING\': 30, \'INFO\': 20, \'ERROR\': 40, \'SUCCESS\': 25}, \'request\': <WSGIRequest: GET \'/kalkulator/dodajRacun?csrfmiddlewaretoken=xqNRrqoThIHZMAIijJMHzrHrNReckOEcSLxNzRbC6XrssNmKt72Ug7a3NMJhKOgM&racun1=Transakcijski+Racun\'>, \'user\': <SimpleLazyObject: <User: goblinsly>>}, {}, {\'racuni\': <QuerySet [<Racun: 1: transakcijski racun, 0.00€ >, <Racun: 1: 3, 0.00€ >, <Racun: goblinsly: Transakcijski Racun, 0.00€ >]>}, {\'block\': <Block Node: main. Contents: [<TextNode: \'\\n\\t<div id="Stanje"> \\n\\t\\t\\t\\n\'>, <django.template.defaulttags.CsrfTokenNode object at 0x03FA2A50>, <TextNode: \' \\t\\t\\t\\t\\t\\t\\t\\t\\t\\t\\t\\n\\t\\t\\t<label>Pr\'>, <For Node: for racun in racuni, tail_len: 3>, <TextNode: \'\\t\\t\\t\\t\\t\\t\\t\\t\\t\\t\\t\\t\\t\\t\\t\\t\\t\\t\\t\\t\\t\\t\\n\\t\\t\'>, <Block Node: izpisStanja. Contents: [<TextNode: \'\\n\\t\\t\\t\'>]>, <TextNode: \'\\n\\t\\t\\t\\t\\t\\t\\t\\n\\t\\t\\t\'>, <Variable Node: warning>, <TextNode: \'\\t\\t\\t\\t\\t\\t\\t\\t\\n\\t\\t\\t\\t\\t\\n\\t\\t</div>\\t\\t\'>, <django.template.defaulttags.CsrfTokenNode object at 0x03F7FA30>, <TextNode: \' \\t\\n\\t\\t\\t<label>Dodaj nov ra\'>, <django.template.defaulttags.CsrfTokenNode object at 0x03FA2350>, <TextNode: \' \\t\\t\\t\\t\\t\\t\\t\\t\\t\\t\\t\\n\\t\\t\\t<label>Iz\'>, <For Node: for racun in racuni, tail_len: 3>, <TextNode: \'\\t\\t\\t\\t\\t\\t\\t\\t\\t\\t\\t\\t\\t\\t\\t\\t\\t\\t\\t\\t\\t\\t\\n\\t\\t\'>]>}]'
"GET /kalkulator/dodajRacun?csrfmiddlewaretoken=xqNRrqoThIHZMAIijJMHzrHrNReckOEcSLxNzRbC6XrssNmKt72Ug7a3NMJhKOgM&racun1=Transakcijski+Racun HTTP/1.1" 200 2762
(0.001) SELECT "django_session"."session_key", "django_session"."session_data", "django_session"."expire_date" FROM "django_session" WHERE ("django_session"."expire_date" > '2017-01-05 19:29:52.962541' AND "django_session"."session_key" = 'u9txi8tulni35b6kgahgojrlgnedzvag'); args=('2017-01-05 19:29:52.962541', 'u9txi8tulni35b6kgahgojrlgnedzvag')
(0.000) SELECT "auth_user"."id", "auth_user"."password", "auth_user"."last_login", "auth_user"."is_superuser", "auth_user"."username", "auth_user"."first_name", "auth_user"."last_name", "auth_user"."email", "auth_user"."is_staff", "auth_user"."is_active", "auth_user"."date_joined" FROM "auth_user" WHERE "auth_user"."id" = 32; args=(32,)
(0.000) SELECT "kalkulator_racun"."id", "kalkulator_racun"."uporabnik_id", "kalkulator_racun"."ime", "kalkulator_racun"."stanje" FROM "kalkulator_racun" WHERE ("kalkulator_racun"."uporabnik_id" = 32 AND "kalkulator_racun"."ime" = 'Transakcijski Racun'); args=(32, 'Transakcijski Racun')
(0.000) SELECT "kalkulator_vnos"."id", "kalkulator_vnos"."racun_id", "kalkulator_vnos"."vrsta", "kalkulator_vnos"."kategorija", "kalkulator_vnos"."znesek", "kalkulator_vnos"."podrobnosti", "kalkulator_vnos"."datum" FROM "kalkulator_vnos" WHERE "kalkulator_vnos"."racun_id" = 88; args=(88,)
(0.000) SELECT "kalkulator_racun"."id", "kalkulator_racun"."uporabnik_id", "kalkulator_racun"."ime", "kalkulator_racun"."stanje" FROM "kalkulator_racun"; args=()
(0.000) SELECT "auth_user"."id", "auth_user"."password", "auth_user"."last_login", "auth_user"."is_superuser", "auth_user"."username", "auth_user"."first_name", "auth_user"."last_name", "auth_user"."email", "auth_user"."is_staff", "auth_user"."is_active", "auth_user"."date_joined" FROM "auth_user" WHERE "auth_user"."id" = 36; args=(36,)
(0.000) SELECT "auth_user"."id", "auth_user"."password", "auth_user"."last_login", "auth_user"."is_superuser", "auth_user"."username", "auth_user"."first_name", "auth_user"."last_name", "auth_user"."email", "auth_user"."is_staff", "auth_user"."is_active", "auth_user"."date_joined" FROM "auth_user" WHERE "auth_user"."id" = 36; args=(36,)
(0.000) SELECT "auth_user"."id", "auth_user"."password", "auth_user"."last_login", "auth_user"."is_superuser", "auth_user"."username", "auth_user"."first_name", "auth_user"."last_name", "auth_user"."email", "auth_user"."is_staff", "auth_user"."is_active", "auth_user"."date_joined" FROM "auth_user" WHERE "auth_user"."id" = 32; args=(32,)
Exception while resolving variable 'warning' in template 'kalkulator/StanjePodrobno.html'.
Traceback (most recent call last):
  File "C:\Program Files (x86)\Python35-32\lib\site-packages\django\template\base.py", line 885, in _resolve_lookup
    current = current[bit]
  File "C:\Program Files (x86)\Python35-32\lib\site-packages\django\template\context.py", line 75, in __getitem__
    raise KeyError(key)
KeyError: 'warning'

During handling of the above exception, another exception occurred:

Traceback (most recent call last):
  File "C:\Program Files (x86)\Python35-32\lib\site-packages\django\template\base.py", line 891, in _resolve_lookup
    if isinstance(current, BaseContext) and getattr(type(current), bit):
AttributeError: type object 'RequestContext' has no attribute 'warning'

During handling of the above exception, another exception occurred:

Traceback (most recent call last):
  File "C:\Program Files (x86)\Python35-32\lib\site-packages\django\template\base.py", line 900, in _resolve_lookup
    current = current[int(bit)]
ValueError: invalid literal for int() with base 10: 'warning'

During handling of the above exception, another exception occurred:

Traceback (most recent call last):
  File "C:\Program Files (x86)\Python35-32\lib\site-packages\django\template\base.py", line 907, in _resolve_lookup
    (bit, current))  # missing attribute
django.template.base.VariableDoesNotExist: Failed lookup for key [warning] in '[{\'None\': None, \'True\': True, \'False\': False}, {\'messages\': <django.contrib.messages.storage.fallback.FallbackStorage object at 0x03F96650>, \'csrf_token\': <SimpleLazyObject: \'EVJAmZ5YHDDUT9Cm5t4HfEM3wcmALPlfZgtwuqSHwSnnzmgOfRkUWkfFw7RFbPXP\'>, \'perms\': <django.contrib.auth.context_processors.PermWrapper object at 0x03F7FED0>, \'DEFAULT_MESSAGE_LEVELS\': {\'DEBUG\': 10, \'WARNING\': 30, \'INFO\': 20, \'ERROR\': 40, \'SUCCESS\': 25}, \'request\': <WSGIRequest: GET \'/kalkulator/StanjePodrobno?csrfmiddlewaretoken=kXuKqXWdkGxi3w1DLdjDHPyONdAm6vPVFieGyoJW9VhLJJF5VBzQov1qN85rwvrv&dropdown=Transakcijski+Racun\'>, \'user\': <SimpleLazyObject: <User: goblinsly>>}, {}, {\'vnosi\': <QuerySet []>, \'vsota\': 0, \'racuni\': <QuerySet [<Racun: 1: transakcijski racun, 0.00€ >, <Racun: 1: 3, 0.00€ >, <Racun: goblinsly: Transakcijski Racun, 0.00€ >]>}, {\'block\': <Block Node: main. Contents: [<TextNode: \'\\n\\t<div id="Stanje"> \\n\\t\\t\\t\\n\'>, <django.template.defaulttags.CsrfTokenNode object at 0x03FA25D0>, <TextNode: \' \\t\\t\\t\\t\\t\\t\\t\\t\\t\\t\\t\\n\\t\\t\\t<label>Pr\'>, <For Node: for racun in racuni, tail_len: 3>, <TextNode: \'\\t\\t\\t\\t\\t\\t\\t\\t\\t\\t\\t\\t\\t\\t\\t\\t\\t\\t\\t\\t\\t\\t\\n\\t\\t\'>, <Block Node: izpisStanja. Contents: [<TextNode: \'\\n\\t\\t\\t\'>]>, <TextNode: \'\\n\\t\\t\\t\\t\\t\\t\\t\\n\\t\\t\\t\'>, <Variable Node: warning>, <TextNode: \'\\t\\t\\t\\t\\t\\t\\t\\t\\n\\t\\t\\t\\t\\t\\n\\t\\t</div>\\t\\t\'>, <django.template.defaulttags.CsrfTokenNode object at 0x03FA2670>, <TextNode: \' \\t\\n\\t\\t\\t<label>Dodaj nov ra\'>, <django.template.defaulttags.CsrfTokenNode object at 0x03FD8310>, <TextNode: \' \\t\\t\\t\\t\\t\\t\\t\\t\\t\\t\\t\\n\\t\\t\\t<label>Iz\'>, <For Node: for racun in racuni, tail_len: 3>, <TextNode: \'\\t\\t\\t\\t\\t\\t\\t\\t\\t\\t\\t\\t\\t\\t\\t\\t\\t\\t\\t\\t\\t\\t\\n\\t\\t\'>]>}]'
"GET /kalkulator/StanjePodrobno?csrfmiddlewaretoken=kXuKqXWdkGxi3w1DLdjDHPyONdAm6vPVFieGyoJW9VhLJJF5VBzQov1qN85rwvrv&dropdown=Transakcijski+Racun HTTP/1.1" 200 2854
(0.001) SELECT "django_session"."session_key", "django_session"."session_data", "django_session"."expire_date" FROM "django_session" WHERE ("django_session"."expire_date" > '2017-01-05 19:29:53.701676' AND "django_session"."session_key" = 'u9txi8tulni35b6kgahgojrlgnedzvag'); args=('2017-01-05 19:29:53.701676', 'u9txi8tulni35b6kgahgojrlgnedzvag')
(0.000) SELECT "auth_user"."id", "auth_user"."password", "auth_user"."last_login", "auth_user"."is_superuser", "auth_user"."username", "auth_user"."first_name", "auth_user"."last_name", "auth_user"."email", "auth_user"."is_staff", "auth_user"."is_active", "auth_user"."date_joined" FROM "auth_user" WHERE "auth_user"."id" = 32; args=(32,)
(0.000) SELECT "kalkulator_racun"."id", "kalkulator_racun"."uporabnik_id", "kalkulator_racun"."ime", "kalkulator_racun"."stanje" FROM "kalkulator_racun"; args=()
(0.000) SELECT "auth_user"."id", "auth_user"."password", "auth_user"."last_login", "auth_user"."is_superuser", "auth_user"."username", "auth_user"."first_name", "auth_user"."last_name", "auth_user"."email", "auth_user"."is_staff", "auth_user"."is_active", "auth_user"."date_joined" FROM "auth_user" WHERE "auth_user"."id" = 36; args=(36,)
(0.000) SELECT "auth_user"."id", "auth_user"."password", "auth_user"."last_login", "auth_user"."is_superuser", "auth_user"."username", "auth_user"."first_name", "auth_user"."last_name", "auth_user"."email", "auth_user"."is_staff", "auth_user"."is_active", "auth_user"."date_joined" FROM "auth_user" WHERE "auth_user"."id" = 36; args=(36,)
(0.001) SELECT "auth_user"."id", "auth_user"."password", "auth_user"."last_login", "auth_user"."is_superuser", "auth_user"."username", "auth_user"."first_name", "auth_user"."last_name", "auth_user"."email", "auth_user"."is_staff", "auth_user"."is_active", "auth_user"."date_joined" FROM "auth_user" WHERE "auth_user"."id" = 32; args=(32,)
Exception while resolving variable 'warning' in template 'kalkulator/vpisiPrihodek.html'.
Traceback (most recent call last):
  File "C:\Program Files (x86)\Python35-32\lib\site-packages\django\template\base.py", line 885, in _resolve_lookup
    current = current[bit]
  File "C:\Program Files (x86)\Python35-32\lib\site-packages\django\template\context.py", line 75, in __getitem__
    raise KeyError(key)
KeyError: 'warning'

During handling of the above exception, another exception occurred:

Traceback (most recent call last):
  File "C:\Program Files (x86)\Python35-32\lib\site-packages\django\template\base.py", line 891, in _resolve_lookup
    if isinstance(current, BaseContext) and getattr(type(current), bit):
AttributeError: type object 'RequestContext' has no attribute 'warning'

During handling of the above exception, another exception occurred:

Traceback (most recent call last):
  File "C:\Program Files (x86)\Python35-32\lib\site-packages\django\template\base.py", line 900, in _resolve_lookup
    current = current[int(bit)]
ValueError: invalid literal for int() with base 10: 'warning'

During handling of the above exception, another exception occurred:

Traceback (most recent call last):
  File "C:\Program Files (x86)\Python35-32\lib\site-packages\django\template\base.py", line 907, in _resolve_lookup
    (bit, current))  # missing attribute
django.template.base.VariableDoesNotExist: Failed lookup for key [warning] in '[{\'None\': None, \'True\': True, \'False\': False}, {\'messages\': <django.contrib.messages.storage.fallback.FallbackStorage object at 0x03FA2630>, \'csrf_token\': <SimpleLazyObject: \'3DgTorIo7Itx9DimMm8gFrFDjGCN3S02oY0PwSv7WXd0PQWOWKotm78fjB7StSCC\'>, \'perms\': <django.contrib.auth.context_processors.PermWrapper object at 0x03FA2B10>, \'DEFAULT_MESSAGE_LEVELS\': {\'DEBUG\': 10, \'WARNING\': 30, \'INFO\': 20, \'ERROR\': 40, \'SUCCESS\': 25}, \'request\': <WSGIRequest: GET \'/kalkulator/vpisiPrihodek.html\'>, \'user\': <SimpleLazyObject: <User: goblinsly>>}, {}, {\'racuni\': <QuerySet [<Racun: 1: transakcijski racun, 0.00€ >, <Racun: 1: 3, 0.00€ >, <Racun: goblinsly: Transakcijski Racun, 0.00€ >]>}, {\'block\': <Block Node: main. Contents: [<TextNode: \'\\n\\n\\t<div id="Obrazec">\\n\\t\\t\\t\'>, <django.template.defaulttags.CsrfTokenNode object at 0x03FA21D0>, <TextNode: \' \\t\\n\\t\\t\\t\\t\\t\\t\\t\\t\\n\\t\\t\\t<label>Kat\'>, <For Node: for racun in racuni, tail_len: 3>, <TextNode: \'\\t\\t\\t\\t\\t\\t\\t\\t\\t\\t\\t\\t\\t\\t\\t\\t\\t\\t\\t\\t\\t\\t\\t\\t\\t\'>, <Block Node: vpisPrihodka. Contents: [<TextNode: \'\\t\\t\\n\\t\\t\'>]>, <TextNode: \'\\t\\n\\t\\t\\n\\t\\t\'>, <Variable Node: warning>, <TextNode: \'\\n\\t\\t\\n\\t</div>\\n\\t\\t\\t\\t\\t\\n\\t</div>\'>]>}]'
"GET /kalkulator/vpisiPrihodek.html HTTP/1.1" 200 2067
(0.001) SELECT "django_session"."session_key", "django_session"."session_data", "django_session"."expire_date" FROM "django_session" WHERE ("django_session"."expire_date" > '2017-01-05 19:29:54.952387' AND "django_session"."session_key" = 'u9txi8tulni35b6kgahgojrlgnedzvag'); args=('2017-01-05 19:29:54.952387', 'u9txi8tulni35b6kgahgojrlgnedzvag')
(0.000) SELECT "auth_user"."id", "auth_user"."password", "auth_user"."last_login", "auth_user"."is_superuser", "auth_user"."username", "auth_user"."first_name", "auth_user"."last_name", "auth_user"."email", "auth_user"."is_staff", "auth_user"."is_active", "auth_user"."date_joined" FROM "auth_user" WHERE "auth_user"."id" = 32; args=(32,)
(0.000) SELECT "kalkulator_racun"."id", "kalkulator_racun"."uporabnik_id", "kalkulator_racun"."ime", "kalkulator_racun"."stanje" FROM "kalkulator_racun"; args=()
(0.000) SELECT "auth_user"."id", "auth_user"."password", "auth_user"."last_login", "auth_user"."is_superuser", "auth_user"."username", "auth_user"."first_name", "auth_user"."last_name", "auth_user"."email", "auth_user"."is_staff", "auth_user"."is_active", "auth_user"."date_joined" FROM "auth_user" WHERE "auth_user"."id" = 36; args=(36,)
(0.001) SELECT "auth_user"."id", "auth_user"."password", "auth_user"."last_login", "auth_user"."is_superuser", "auth_user"."username", "auth_user"."first_name", "auth_user"."last_name", "auth_user"."email", "auth_user"."is_staff", "auth_user"."is_active", "auth_user"."date_joined" FROM "auth_user" WHERE "auth_user"."id" = 36; args=(36,)
(0.000) SELECT "auth_user"."id", "auth_user"."password", "auth_user"."last_login", "auth_user"."is_superuser", "auth_user"."username", "auth_user"."first_name", "auth_user"."last_name", "auth_user"."email", "auth_user"."is_staff", "auth_user"."is_active", "auth_user"."date_joined" FROM "auth_user" WHERE "auth_user"."id" = 32; args=(32,)
Exception while resolving variable 'warning' in template 'kalkulator/vpisiOdhodek.html'.
Traceback (most recent call last):
  File "C:\Program Files (x86)\Python35-32\lib\site-packages\django\template\base.py", line 885, in _resolve_lookup
    current = current[bit]
  File "C:\Program Files (x86)\Python35-32\lib\site-packages\django\template\context.py", line 75, in __getitem__
    raise KeyError(key)
KeyError: 'warning'

During handling of the above exception, another exception occurred:

Traceback (most recent call last):
  File "C:\Program Files (x86)\Python35-32\lib\site-packages\django\template\base.py", line 891, in _resolve_lookup
    if isinstance(current, BaseContext) and getattr(type(current), bit):
AttributeError: type object 'RequestContext' has no attribute 'warning'

During handling of the above exception, another exception occurred:

Traceback (most recent call last):
  File "C:\Program Files (x86)\Python35-32\lib\site-packages\django\template\base.py", line 900, in _resolve_lookup
    current = current[int(bit)]
ValueError: invalid literal for int() with base 10: 'warning'

During handling of the above exception, another exception occurred:

Traceback (most recent call last):
  File "C:\Program Files (x86)\Python35-32\lib\site-packages\django\template\base.py", line 907, in _resolve_lookup
    (bit, current))  # missing attribute
django.template.base.VariableDoesNotExist: Failed lookup for key [warning] in '[{\'None\': None, \'True\': True, \'False\': False}, {\'messages\': <django.contrib.messages.storage.fallback.FallbackStorage object at 0x03FA2B90>, \'csrf_token\': <SimpleLazyObject: \'7hVk1LtwQrfLiKIpdxzoxTb7VDsECsVKsCFg9cgfFGZeYXmRnVPBezEJVyXJ2sxk\'>, \'perms\': <django.contrib.auth.context_processors.PermWrapper object at 0x03FD89D0>, \'DEFAULT_MESSAGE_LEVELS\': {\'DEBUG\': 10, \'WARNING\': 30, \'INFO\': 20, \'ERROR\': 40, \'SUCCESS\': 25}, \'request\': <WSGIRequest: GET \'/kalkulator/vpisiOdhodek.html\'>, \'user\': <SimpleLazyObject: <User: goblinsly>>}, {}, {\'racuni\': <QuerySet [<Racun: 1: transakcijski racun, 0.00€ >, <Racun: 1: 3, 0.00€ >, <Racun: goblinsly: Transakcijski Racun, 0.00€ >]>}, {\'block\': <Block Node: main. Contents: [<TextNode: \'\\n\\t\\t\\t\\t\\n\\t\\t<div id="Obrazec"\'>, <django.template.defaulttags.CsrfTokenNode object at 0x03FD83D0>, <TextNode: \' \\t\\t\\t\\t\\t\\t\\t\\t\\t\\t\\t\\n\\t\\t\\t\\t\\t<label>\'>, <For Node: for racun in racuni, tail_len: 3>, <TextNode: \'\\t\\t\\t\\t\\t\\t\\t\\t\\t\\t\\t\\t\\t\\t\\t\\n\\t\\t\\t\\t\\t</se\'>, <Block Node: vpisOdhodka. Contents: [<TextNode: \'\\n\\t\\t\\t\\t\\n\\t\\t\\t\\t\'>]>, <TextNode: \'\\n\\t\\t\\t\\t\\n\\t\\t\\t\\t\'>, <Variable Node: warning>, <TextNode: \'\\n\\t\\t\\t\\t\\t\\t\\n\\t\\t\\t</div>\\t\\t\\n\\t\\t\\n\\t\\t\'>]>}]'
"GET /kalkulator/vpisiOdhodek.html HTTP/1.1" 200 2177
(0.001) SELECT "django_session"."session_key", "django_session"."session_data", "django_session"."expire_date" FROM "django_session" WHERE ("django_session"."expire_date" > '2017-01-05 19:29:55.616133' AND "django_session"."session_key" = 'u9txi8tulni35b6kgahgojrlgnedzvag'); args=('2017-01-05 19:29:55.616133', 'u9txi8tulni35b6kgahgojrlgnedzvag')
(0.000) SELECT "auth_user"."id", "auth_user"."password", "auth_user"."last_login", "auth_user"."is_superuser", "auth_user"."username", "auth_user"."first_name", "auth_user"."last_name", "auth_user"."email", "auth_user"."is_staff", "auth_user"."is_active", "auth_user"."date_joined" FROM "auth_user" WHERE "auth_user"."id" = 32; args=(32,)
(0.001) SELECT "kalkulator_racun"."id", "kalkulator_racun"."uporabnik_id", "kalkulator_racun"."ime", "kalkulator_racun"."stanje" FROM "kalkulator_racun"; args=()
(0.000) SELECT "auth_user"."id", "auth_user"."password", "auth_user"."last_login", "auth_user"."is_superuser", "auth_user"."username", "auth_user"."first_name", "auth_user"."last_name", "auth_user"."email", "auth_user"."is_staff", "auth_user"."is_active", "auth_user"."date_joined" FROM "auth_user" WHERE "auth_user"."id" = 36; args=(36,)
(0.000) SELECT "auth_user"."id", "auth_user"."password", "auth_user"."last_login", "auth_user"."is_superuser", "auth_user"."username", "auth_user"."first_name", "auth_user"."last_name", "auth_user"."email", "auth_user"."is_staff", "auth_user"."is_active", "auth_user"."date_joined" FROM "auth_user" WHERE "auth_user"."id" = 36; args=(36,)
(0.000) SELECT "auth_user"."id", "auth_user"."password", "auth_user"."last_login", "auth_user"."is_superuser", "auth_user"."username", "auth_user"."first_name", "auth_user"."last_name", "auth_user"."email", "auth_user"."is_staff", "auth_user"."is_active", "auth_user"."date_joined" FROM "auth_user" WHERE "auth_user"."id" = 32; args=(32,)
Exception while resolving variable 'warning' in template 'kalkulator/porocila.html'.
Traceback (most recent call last):
  File "C:\Program Files (x86)\Python35-32\lib\site-packages\django\template\base.py", line 885, in _resolve_lookup
    current = current[bit]
  File "C:\Program Files (x86)\Python35-32\lib\site-packages\django\template\context.py", line 75, in __getitem__
    raise KeyError(key)
KeyError: 'warning'

During handling of the above exception, another exception occurred:

Traceback (most recent call last):
  File "C:\Program Files (x86)\Python35-32\lib\site-packages\django\template\base.py", line 891, in _resolve_lookup
    if isinstance(current, BaseContext) and getattr(type(current), bit):
AttributeError: type object 'RequestContext' has no attribute 'warning'

During handling of the above exception, another exception occurred:

Traceback (most recent call last):
  File "C:\Program Files (x86)\Python35-32\lib\site-packages\django\template\base.py", line 900, in _resolve_lookup
    current = current[int(bit)]
ValueError: invalid literal for int() with base 10: 'warning'

During handling of the above exception, another exception occurred:

Traceback (most recent call last):
  File "C:\Program Files (x86)\Python35-32\lib\site-packages\django\template\base.py", line 907, in _resolve_lookup
    (bit, current))  # missing attribute
django.template.base.VariableDoesNotExist: Failed lookup for key [warning] in '[{\'None\': None, \'True\': True, \'False\': False}, {\'messages\': <django.contrib.messages.storage.fallback.FallbackStorage object at 0x03FD81B0>, \'csrf_token\': <SimpleLazyObject: <function csrf.<locals>._get_val at 0x03FCBE88>>, \'perms\': <django.contrib.auth.context_processors.PermWrapper object at 0x03FD8B90>, \'DEFAULT_MESSAGE_LEVELS\': {\'DEBUG\': 10, \'WARNING\': 30, \'INFO\': 20, \'ERROR\': 40, \'SUCCESS\': 25}, \'request\': <WSGIRequest: GET \'/kalkulator/porocila.html\'>, \'user\': <SimpleLazyObject: <User: goblinsly>>}, {}, {\'racuni\': <QuerySet [<Racun: 1: transakcijski racun, 0.00€ >, <Racun: 1: 3, 0.00€ >, <Racun: goblinsly: Transakcijski Racun, 0.00€ >]>}, {\'block\': <Block Node: main. Contents: [<TextNode: \'\\n\\t<div id="Porocilo"> \\n\\t\\n\'>, <For Node: for racun in racuni, tail_len: 3>, <TextNode: \'\\t\\t\\t\\t\\t\\t\\t\\t\\t\\t\\t\\t\\t\\t\\t\\t\\t\\t\\t\\t\\t\\t\\n\\t\\t\'>, <Block Node: izpisStanja. Contents: [<TextNode: \'\\n\\t\\t\\t\\n\\t\\t\\t\'>]>, <TextNode: \'\\n\\t\\t\\t\\n\\t\\t\\t\'>, <Variable Node: warning>, <TextNode: \'\\n\\t\\t\\t\\n\\t\\t</div>\\t\\n\\t\\t\\n\\t</div>\'>]>}]'
"GET /kalkulator/porocila.html HTTP/1.1" 200 1848
(0.001) SELECT "django_session"."session_key", "django_session"."session_data", "django_session"."expire_date" FROM "django_session" WHERE ("django_session"."expire_date" > '2017-01-05 19:30:00.554688' AND "django_session"."session_key" = 'u9txi8tulni35b6kgahgojrlgnedzvag'); args=('2017-01-05 19:30:00.554688', 'u9txi8tulni35b6kgahgojrlgnedzvag')
(0.001) SELECT "auth_user"."id", "auth_user"."password", "auth_user"."last_login", "auth_user"."is_superuser", "auth_user"."username", "auth_user"."first_name", "auth_user"."last_name", "auth_user"."email", "auth_user"."is_staff", "auth_user"."is_active", "auth_user"."date_joined" FROM "auth_user" WHERE "auth_user"."id" = 32; args=(32,)
(0.000) SELECT (1) AS "a" FROM "auth_group" INNER JOIN "auth_user_groups" ON ("auth_group"."id" = "auth_user_groups"."group_id") WHERE ("auth_user_groups"."user_id" = 32 AND "auth_group"."name" = 'user') LIMIT 1; args=(32, 'user')
(0.000) SELECT "auth_user"."id", "auth_user"."password", "auth_user"."last_login", "auth_user"."is_superuser", "auth_user"."username", "auth_user"."first_name", "auth_user"."last_name", "auth_user"."email", "auth_user"."is_staff", "auth_user"."is_active", "auth_user"."date_joined" FROM "auth_user"; args=()
Exception while resolving variable 'warning' in template 'kalkulator/administracija.html'.
Traceback (most recent call last):
  File "C:\Program Files (x86)\Python35-32\lib\site-packages\django\template\base.py", line 885, in _resolve_lookup
    current = current[bit]
  File "C:\Program Files (x86)\Python35-32\lib\site-packages\django\template\context.py", line 75, in __getitem__
    raise KeyError(key)
KeyError: 'warning'

During handling of the above exception, another exception occurred:

Traceback (most recent call last):
  File "C:\Program Files (x86)\Python35-32\lib\site-packages\django\template\base.py", line 891, in _resolve_lookup
    if isinstance(current, BaseContext) and getattr(type(current), bit):
AttributeError: type object 'RequestContext' has no attribute 'warning'

During handling of the above exception, another exception occurred:

Traceback (most recent call last):
  File "C:\Program Files (x86)\Python35-32\lib\site-packages\django\template\base.py", line 900, in _resolve_lookup
    current = current[int(bit)]
ValueError: invalid literal for int() with base 10: 'warning'

During handling of the above exception, another exception occurred:

Traceback (most recent call last):
  File "C:\Program Files (x86)\Python35-32\lib\site-packages\django\template\base.py", line 907, in _resolve_lookup
    (bit, current))  # missing attribute
django.template.base.VariableDoesNotExist: Failed lookup for key [warning] in '[{\'None\': None, \'True\': True, \'False\': False}, {\'messages\': <django.contrib.messages.storage.fallback.FallbackStorage object at 0x03FDC050>, \'csrf_token\': <SimpleLazyObject: \'HgQtjboUHz3W00djaqUjIRIUfSfaWRvy2BAprCbDwONpGdRLkOawpxbwfNKfmR78\'>, \'perms\': <django.contrib.auth.context_processors.PermWrapper object at 0x03F7FDB0>, \'DEFAULT_MESSAGE_LEVELS\': {\'DEBUG\': 10, \'WARNING\': 30, \'INFO\': 20, \'ERROR\': 40, \'SUCCESS\': 25}, \'request\': <WSGIRequest: GET \'/kalkulator/administracija.html\'>, \'user\': <SimpleLazyObject: <User: goblinsly>>}, {}, {\'uporabniki\': <QuerySet [<User: goblinsly>, <User: 1>]>}, {\'block\': <Block Node: main. Contents: [<TextNode: \'\\n\\t<div id="Stanje"> \\n\\t\\t\\t\\t\'>, <django.template.defaulttags.CsrfTokenNode object at 0x03F7F9D0>, <TextNode: \' \\t\\t\\t\\t\\t\\t\\t\\t\\t\\t\\t\\n\\t\\t\\t<label>Pr\'>, <For Node: for uporabnik in uporabniki, tail_len: 3>, <TextNode: \'\\t\\t\\t\\t\\t\\t\\t\\t\\t\\t\\t\\t\\t\\t\\t\\t\\t\\t\\t\\t\\t\\t\\n\\t\\t\'>, <Variable Node: warning>, <TextNode: \'\\t\\t\\t\\t\\t\\t\\t\\t\\n\\t\\t\\t\\t\\t\\n\\t\\t</div>\\t\\t\'>]>}]'
"GET /kalkulator/administracija.html HTTP/1.1" 200 1663
(0.001) SELECT "django_session"."session_key", "django_session"."session_data", "django_session"."expire_date" FROM "django_session" WHERE ("django_session"."expire_date" > '2017-01-05 19:30:05.829698' AND "django_session"."session_key" = 'u9txi8tulni35b6kgahgojrlgnedzvag'); args=('2017-01-05 19:30:05.829698', 'u9txi8tulni35b6kgahgojrlgnedzvag')
(0.000) SELECT "auth_user"."id", "auth_user"."password", "auth_user"."last_login", "auth_user"."is_superuser", "auth_user"."username", "auth_user"."first_name", "auth_user"."last_name", "auth_user"."email", "auth_user"."is_staff", "auth_user"."is_active", "auth_user"."date_joined" FROM "auth_user" WHERE "auth_user"."id" = 32; args=(32,)
(0.000) SELECT (1) AS "a" FROM "auth_group" INNER JOIN "auth_user_groups" ON ("auth_group"."id" = "auth_user_groups"."group_id") WHERE ("auth_user_groups"."user_id" = 32 AND "auth_group"."name" = 'user') LIMIT 1; args=(32, 'user')
(0.000) SELECT "auth_user"."id", "auth_user"."password", "auth_user"."last_login", "auth_user"."is_superuser", "auth_user"."username", "auth_user"."first_name", "auth_user"."last_name", "auth_user"."email", "auth_user"."is_staff", "auth_user"."is_active", "auth_user"."date_joined" FROM "auth_user" WHERE "auth_user"."username" = '1'; args=('1',)
(0.000) SELECT "kalkulator_racun"."id", "kalkulator_racun"."uporabnik_id", "kalkulator_racun"."ime", "kalkulator_racun"."stanje" FROM "kalkulator_racun" WHERE "kalkulator_racun"."uporabnik_id" IN (36); args=(36,)
(0.000) BEGIN; args=None
(0.000) DELETE FROM "django_admin_log" WHERE "django_admin_log"."user_id" IN (36); args=(36,)
(0.001) DELETE FROM "auth_user_groups" WHERE "auth_user_groups"."user_id" IN (36); args=(36,)
(0.000) DELETE FROM "auth_user_user_permissions" WHERE "auth_user_user_permissions"."user_id" IN (36); args=(36,)
(0.001) DELETE FROM "kalkulator_vnos" WHERE "kalkulator_vnos"."racun_id" IN (72, 74); args=(72, 74)
(0.000) UPDATE "kalkulator_racun" SET "uporabnik_id" = NULL WHERE "kalkulator_racun"."id" IN (72, 74); args=(72, 74)
(0.000) DELETE FROM "auth_user" WHERE "auth_user"."id" IN (36); args=(36,)
(0.000) DELETE FROM "kalkulator_racun" WHERE "kalkulator_racun"."id" IN (72, 74); args=(72, 74)
(0.000) SELECT "auth_user"."id", "auth_user"."password", "auth_user"."last_login", "auth_user"."is_superuser", "auth_user"."username", "auth_user"."first_name", "auth_user"."last_name", "auth_user"."email", "auth_user"."is_staff", "auth_user"."is_active", "auth_user"."date_joined" FROM "auth_user"; args=()
"GET /kalkulator/AdministracijaPodrobno?csrfmiddlewaretoken=HgQtjboUHz3W00djaqUjIRIUfSfaWRvy2BAprCbDwONpGdRLkOawpxbwfNKfmR78&dropdown=1 HTTP/1.1" 200 1613
(0.000) SELECT "django_session"."session_key", "django_session"."session_data", "django_session"."expire_date" FROM "django_session" WHERE ("django_session"."expire_date" > '2017-01-05 19:30:33.783661' AND "django_session"."session_key" = 'u9txi8tulni35b6kgahgojrlgnedzvag'); args=('2017-01-05 19:30:33.783661', 'u9txi8tulni35b6kgahgojrlgnedzvag')
(0.000) SELECT "auth_user"."id", "auth_user"."password", "auth_user"."last_login", "auth_user"."is_superuser", "auth_user"."username", "auth_user"."first_name", "auth_user"."last_name", "auth_user"."email", "auth_user"."is_staff", "auth_user"."is_active", "auth_user"."date_joined" FROM "auth_user" WHERE "auth_user"."id" = 32; args=(32,)
(0.001) SELECT (1) AS "a" FROM "auth_group" INNER JOIN "auth_user_groups" ON ("auth_group"."id" = "auth_user_groups"."group_id") WHERE ("auth_user_groups"."user_id" = 32 AND "auth_group"."name" = 'user') LIMIT 1; args=(32, 'user')
(0.000) SELECT "auth_user"."id", "auth_user"."password", "auth_user"."last_login", "auth_user"."is_superuser", "auth_user"."username", "auth_user"."first_name", "auth_user"."last_name", "auth_user"."email", "auth_user"."is_staff", "auth_user"."is_active", "auth_user"."date_joined" FROM "auth_user"; args=()
Exception while resolving variable 'warning' in template 'kalkulator/administracija.html'.
Traceback (most recent call last):
  File "C:\Program Files (x86)\Python35-32\lib\site-packages\django\template\base.py", line 885, in _resolve_lookup
    current = current[bit]
  File "C:\Program Files (x86)\Python35-32\lib\site-packages\django\template\context.py", line 75, in __getitem__
    raise KeyError(key)
KeyError: 'warning'

During handling of the above exception, another exception occurred:

Traceback (most recent call last):
  File "C:\Program Files (x86)\Python35-32\lib\site-packages\django\template\base.py", line 891, in _resolve_lookup
    if isinstance(current, BaseContext) and getattr(type(current), bit):
AttributeError: type object 'RequestContext' has no attribute 'warning'

During handling of the above exception, another exception occurred:

Traceback (most recent call last):
  File "C:\Program Files (x86)\Python35-32\lib\site-packages\django\template\base.py", line 900, in _resolve_lookup
    current = current[int(bit)]
ValueError: invalid literal for int() with base 10: 'warning'

During handling of the above exception, another exception occurred:

Traceback (most recent call last):
  File "C:\Program Files (x86)\Python35-32\lib\site-packages\django\template\base.py", line 907, in _resolve_lookup
    (bit, current))  # missing attribute
django.template.base.VariableDoesNotExist: Failed lookup for key [warning] in '[{\'None\': None, \'True\': True, \'False\': False}, {\'messages\': <django.contrib.messages.storage.fallback.FallbackStorage object at 0x03FD8F70>, \'csrf_token\': <SimpleLazyObject: \'lO0j7mdcdyF4b7BjHF4V7R1sopOOhksvG9KffN0V2NpxRkfLR3k8Oxu4okjTHk45\'>, \'perms\': <django.contrib.auth.context_processors.PermWrapper object at 0x03FE3130>, \'DEFAULT_MESSAGE_LEVELS\': {\'DEBUG\': 10, \'WARNING\': 30, \'INFO\': 20, \'ERROR\': 40, \'SUCCESS\': 25}, \'request\': <WSGIRequest: GET \'/kalkulator/administracija.html\'>, \'user\': <SimpleLazyObject: <User: goblinsly>>}, {}, {\'uporabniki\': <QuerySet [<User: goblinsly>]>}, {\'block\': <Block Node: main. Contents: [<TextNode: \'\\n\\t<div id="Stanje"> \\n\\t\\t\\t\\t\'>, <django.template.defaulttags.CsrfTokenNode object at 0x03FE34F0>, <TextNode: \' \\t\\t\\t\\t\\t\\t\\t\\t\\t\\t\\t\\n\\t\\t\\t<label>Se\'>, <For Node: for uporabnik in uporabniki, tail_len: 3>, <TextNode: \'\\t\\t\\t\\t\\t\\t\\t\\t\\t\\t\\t\\t\\t\\t\\t\\t\\t\\t\\t\\t\\t\\t\\n\\t\\t\'>, <Variable Node: warning>, <TextNode: \'\\t\\t\\t\\t\\t\\t\\t\\t\\n\\t\\t\\t\\t\\t\\n\\t\\t</div>\\t\\t\'>]>}]'
"GET /kalkulator/administracija.html HTTP/1.1" 200 1589
(0.000) SELECT "django_session"."session_key", "django_session"."session_data", "django_session"."expire_date" FROM "django_session" WHERE ("django_session"."expire_date" > '2017-01-05 19:30:38.490901' AND "django_session"."session_key" = 'u9txi8tulni35b6kgahgojrlgnedzvag'); args=('2017-01-05 19:30:38.490901', 'u9txi8tulni35b6kgahgojrlgnedzvag')
(0.000) SELECT "auth_user"."id", "auth_user"."password", "auth_user"."last_login", "auth_user"."is_superuser", "auth_user"."username", "auth_user"."first_name", "auth_user"."last_name", "auth_user"."email", "auth_user"."is_staff", "auth_user"."is_active", "auth_user"."date_joined" FROM "auth_user" WHERE "auth_user"."id" = 32; args=(32,)
(0.001) SELECT "kalkulator_racun"."id", "kalkulator_racun"."uporabnik_id", "kalkulator_racun"."ime", "kalkulator_racun"."stanje" FROM "kalkulator_racun"; args=()
(0.000) SELECT "auth_user"."id", "auth_user"."password", "auth_user"."last_login", "auth_user"."is_superuser", "auth_user"."username", "auth_user"."first_name", "auth_user"."last_name", "auth_user"."email", "auth_user"."is_staff", "auth_user"."is_active", "auth_user"."date_joined" FROM "auth_user" WHERE "auth_user"."id" = 32; args=(32,)
Exception while resolving variable 'warning' in template 'kalkulator/stanje.html'.
Traceback (most recent call last):
  File "C:\Program Files (x86)\Python35-32\lib\site-packages\django\template\base.py", line 885, in _resolve_lookup
    current = current[bit]
  File "C:\Program Files (x86)\Python35-32\lib\site-packages\django\template\context.py", line 75, in __getitem__
    raise KeyError(key)
KeyError: 'warning'

During handling of the above exception, another exception occurred:

Traceback (most recent call last):
  File "C:\Program Files (x86)\Python35-32\lib\site-packages\django\template\base.py", line 891, in _resolve_lookup
    if isinstance(current, BaseContext) and getattr(type(current), bit):
AttributeError: type object 'RequestContext' has no attribute 'warning'

During handling of the above exception, another exception occurred:

Traceback (most recent call last):
  File "C:\Program Files (x86)\Python35-32\lib\site-packages\django\template\base.py", line 900, in _resolve_lookup
    current = current[int(bit)]
ValueError: invalid literal for int() with base 10: 'warning'

During handling of the above exception, another exception occurred:

Traceback (most recent call last):
  File "C:\Program Files (x86)\Python35-32\lib\site-packages\django\template\base.py", line 907, in _resolve_lookup
    (bit, current))  # missing attribute
django.template.base.VariableDoesNotExist: Failed lookup for key [warning] in '[{\'None\': None, \'True\': True, \'False\': False}, {\'messages\': <django.contrib.messages.storage.fallback.FallbackStorage object at 0x03FD8530>, \'csrf_token\': <SimpleLazyObject: \'D9l6R7VQhojTEs6gNBboXRGzOnNF5kvKYu52ZyIz6D3mkFKIXZrBEx9bOiiKvk7k\'>, \'perms\': <django.contrib.auth.context_processors.PermWrapper object at 0x03FE3870>, \'DEFAULT_MESSAGE_LEVELS\': {\'DEBUG\': 10, \'WARNING\': 30, \'INFO\': 20, \'ERROR\': 40, \'SUCCESS\': 25}, \'request\': <WSGIRequest: GET \'/kalkulator/stanje.html\'>, \'user\': <SimpleLazyObject: <User: goblinsly>>}, {}, {\'racuni\': <QuerySet [<Racun: goblinsly: Transakcijski Racun, 0.00€ >]>}, {\'block\': <Block Node: main. Contents: [<TextNode: \'\\n\\t<div id="Stanje"> \\n\\t\\t\\t\\n\'>, <django.template.defaulttags.CsrfTokenNode object at 0x03FE3DD0>, <TextNode: \' \\t\\t\\t\\t\\t\\t\\t\\t\\t\\t\\t\\n\\t\\t\\t<label>Pr\'>, <For Node: for racun in racuni, tail_len: 3>, <TextNode: \'\\t\\t\\t\\t\\t\\t\\t\\t\\t\\t\\t\\t\\t\\t\\t\\t\\t\\t\\t\\t\\t\\t\\n\\t\\t\'>, <Block Node: izpisStanja. Contents: [<TextNode: \'\\n\\t\\t\\t\'>]>, <TextNode: \'\\n\\t\\t\\t\\t\\t\\t\\t\\n\\t\\t\\t\'>, <Variable Node: warning>, <TextNode: \'\\t\\t\\t\\t\\t\\t\\t\\t\\n\\t\\t\\t\\t\\t\\n\\t\\t</div>\\t\\t\'>, <django.template.defaulttags.CsrfTokenNode object at 0x03FE37F0>, <TextNode: \' \\t\\n\\t\\t\\t<label>Dodaj nov ra\'>, <django.template.defaulttags.CsrfTokenNode object at 0x03FE3970>, <TextNode: \' \\t\\t\\t\\t\\t\\t\\t\\t\\t\\t\\t\\n\\t\\t\\t<label>Iz\'>, <For Node: for racun in racuni, tail_len: 3>, <TextNode: \'\\t\\t\\t\\t\\t\\t\\t\\t\\t\\t\\t\\t\\t\\t\\t\\t\\t\\t\\t\\t\\t\\t\\n\\t\\t\'>]>}]'
"GET /kalkulator/stanje.html HTTP/1.1" 200 2662
(0.000) SELECT "django_session"."session_key", "django_session"."session_data", "django_session"."expire_date" FROM "django_session" WHERE ("django_session"."expire_date" > '2017-01-05 19:30:39.558716' AND "django_session"."session_key" = 'u9txi8tulni35b6kgahgojrlgnedzvag'); args=('2017-01-05 19:30:39.558716', 'u9txi8tulni35b6kgahgojrlgnedzvag')
(0.001) SELECT "auth_user"."id", "auth_user"."password", "auth_user"."last_login", "auth_user"."is_superuser", "auth_user"."username", "auth_user"."first_name", "auth_user"."last_name", "auth_user"."email", "auth_user"."is_staff", "auth_user"."is_active", "auth_user"."date_joined" FROM "auth_user" WHERE "auth_user"."id" = 32; args=(32,)
(0.000) SELECT "kalkulator_racun"."id", "kalkulator_racun"."uporabnik_id", "kalkulator_racun"."ime", "kalkulator_racun"."stanje" FROM "kalkulator_racun"; args=()
(0.000) SELECT "auth_user"."id", "auth_user"."password", "auth_user"."last_login", "auth_user"."is_superuser", "auth_user"."username", "auth_user"."first_name", "auth_user"."last_name", "auth_user"."email", "auth_user"."is_staff", "auth_user"."is_active", "auth_user"."date_joined" FROM "auth_user" WHERE "auth_user"."id" = 32; args=(32,)
Exception while resolving variable 'warning' in template 'kalkulator/vpisiPrihodek.html'.
Traceback (most recent call last):
  File "C:\Program Files (x86)\Python35-32\lib\site-packages\django\template\base.py", line 885, in _resolve_lookup
    current = current[bit]
  File "C:\Program Files (x86)\Python35-32\lib\site-packages\django\template\context.py", line 75, in __getitem__
    raise KeyError(key)
KeyError: 'warning'

During handling of the above exception, another exception occurred:

Traceback (most recent call last):
  File "C:\Program Files (x86)\Python35-32\lib\site-packages\django\template\base.py", line 891, in _resolve_lookup
    if isinstance(current, BaseContext) and getattr(type(current), bit):
AttributeError: type object 'RequestContext' has no attribute 'warning'

During handling of the above exception, another exception occurred:

Traceback (most recent call last):
  File "C:\Program Files (x86)\Python35-32\lib\site-packages\django\template\base.py", line 900, in _resolve_lookup
    current = current[int(bit)]
ValueError: invalid literal for int() with base 10: 'warning'

During handling of the above exception, another exception occurred:

Traceback (most recent call last):
  File "C:\Program Files (x86)\Python35-32\lib\site-packages\django\template\base.py", line 907, in _resolve_lookup
    (bit, current))  # missing attribute
django.template.base.VariableDoesNotExist: Failed lookup for key [warning] in '[{\'None\': None, \'True\': True, \'False\': False}, {\'messages\': <django.contrib.messages.storage.fallback.FallbackStorage object at 0x03FEF0B0>, \'csrf_token\': <SimpleLazyObject: \'YXynDUxmbgn0G9utWC7YS0WTz9glOXS5jiijLlk50v7tmm8V60nbzGpvz4LqeXuF\'>, \'perms\': <django.contrib.auth.context_processors.PermWrapper object at 0x03FEFBD0>, \'DEFAULT_MESSAGE_LEVELS\': {\'DEBUG\': 10, \'WARNING\': 30, \'INFO\': 20, \'ERROR\': 40, \'SUCCESS\': 25}, \'request\': <WSGIRequest: GET \'/kalkulator/vpisiPrihodek.html\'>, \'user\': <SimpleLazyObject: <User: goblinsly>>}, {}, {\'racuni\': <QuerySet [<Racun: goblinsly: Transakcijski Racun, 0.00€ >]>}, {\'block\': <Block Node: main. Contents: [<TextNode: \'\\n\\n\\t<div id="Obrazec">\\n\\t\\t\\t\'>, <django.template.defaulttags.CsrfTokenNode object at 0x03FEF950>, <TextNode: \' \\t\\n\\t\\t\\t\\t\\t\\t\\t\\t\\n\\t\\t\\t<label>Kat\'>, <For Node: for racun in racuni, tail_len: 3>, <TextNode: \'\\t\\t\\t\\t\\t\\t\\t\\t\\t\\t\\t\\t\\t\\t\\t\\t\\t\\t\\t\\t\\t\\t\\t\\t\\t\'>, <Block Node: vpisPrihodka. Contents: [<TextNode: \'\\t\\t\\n\\t\\t\'>]>, <TextNode: \'\\t\\n\\t\\t\\n\\t\\t\'>, <Variable Node: warning>, <TextNode: \'\\n\\t\\t\\n\\t</div>\\n\\t\\t\\t\\t\\t\\n\\t</div>\'>]>}]'
"GET /kalkulator/vpisiPrihodek.html HTTP/1.1" 200 2017
(0.000) SELECT "django_session"."session_key", "django_session"."session_data", "django_session"."expire_date" FROM "django_session" WHERE ("django_session"."expire_date" > '2017-01-05 19:30:40.393615' AND "django_session"."session_key" = 'u9txi8tulni35b6kgahgojrlgnedzvag'); args=('2017-01-05 19:30:40.393615', 'u9txi8tulni35b6kgahgojrlgnedzvag')
(0.001) SELECT "auth_user"."id", "auth_user"."password", "auth_user"."last_login", "auth_user"."is_superuser", "auth_user"."username", "auth_user"."first_name", "auth_user"."last_name", "auth_user"."email", "auth_user"."is_staff", "auth_user"."is_active", "auth_user"."date_joined" FROM "auth_user" WHERE "auth_user"."id" = 32; args=(32,)
(0.000) SELECT "kalkulator_racun"."id", "kalkulator_racun"."uporabnik_id", "kalkulator_racun"."ime", "kalkulator_racun"."stanje" FROM "kalkulator_racun"; args=()
(0.000) SELECT "auth_user"."id", "auth_user"."password", "auth_user"."last_login", "auth_user"."is_superuser", "auth_user"."username", "auth_user"."first_name", "auth_user"."last_name", "auth_user"."email", "auth_user"."is_staff", "auth_user"."is_active", "auth_user"."date_joined" FROM "auth_user" WHERE "auth_user"."id" = 32; args=(32,)
Exception while resolving variable 'warning' in template 'kalkulator/vpisiOdhodek.html'.
Traceback (most recent call last):
  File "C:\Program Files (x86)\Python35-32\lib\site-packages\django\template\base.py", line 885, in _resolve_lookup
    current = current[bit]
  File "C:\Program Files (x86)\Python35-32\lib\site-packages\django\template\context.py", line 75, in __getitem__
    raise KeyError(key)
KeyError: 'warning'

During handling of the above exception, another exception occurred:

Traceback (most recent call last):
  File "C:\Program Files (x86)\Python35-32\lib\site-packages\django\template\base.py", line 891, in _resolve_lookup
    if isinstance(current, BaseContext) and getattr(type(current), bit):
AttributeError: type object 'RequestContext' has no attribute 'warning'

During handling of the above exception, another exception occurred:

Traceback (most recent call last):
  File "C:\Program Files (x86)\Python35-32\lib\site-packages\django\template\base.py", line 900, in _resolve_lookup
    current = current[int(bit)]
ValueError: invalid literal for int() with base 10: 'warning'

During handling of the above exception, another exception occurred:

Traceback (most recent call last):
  File "C:\Program Files (x86)\Python35-32\lib\site-packages\django\template\base.py", line 907, in _resolve_lookup
    (bit, current))  # missing attribute
django.template.base.VariableDoesNotExist: Failed lookup for key [warning] in '[{\'None\': None, \'True\': True, \'False\': False}, {\'messages\': <django.contrib.messages.storage.fallback.FallbackStorage object at 0x03FEF650>, \'csrf_token\': <SimpleLazyObject: \'T268q8l5FBHFmGmpcvQBjoXQ119R2H0BenQ4yz8OuQr82T0RmT6O04qs1WEWsHCb\'>, \'perms\': <django.contrib.auth.context_processors.PermWrapper object at 0x03FE3ED0>, \'DEFAULT_MESSAGE_LEVELS\': {\'DEBUG\': 10, \'WARNING\': 30, \'INFO\': 20, \'ERROR\': 40, \'SUCCESS\': 25}, \'request\': <WSGIRequest: GET \'/kalkulator/vpisiOdhodek.html\'>, \'user\': <SimpleLazyObject: <User: goblinsly>>}, {}, {\'racuni\': <QuerySet [<Racun: goblinsly: Transakcijski Racun, 0.00€ >]>}, {\'block\': <Block Node: main. Contents: [<TextNode: \'\\n\\t\\t\\t\\t\\n\\t\\t<div id="Obrazec"\'>, <django.template.defaulttags.CsrfTokenNode object at 0x03FE3D70>, <TextNode: \' \\t\\t\\t\\t\\t\\t\\t\\t\\t\\t\\t\\n\\t\\t\\t\\t\\t<label>\'>, <For Node: for racun in racuni, tail_len: 3>, <TextNode: \'\\t\\t\\t\\t\\t\\t\\t\\t\\t\\t\\t\\t\\t\\t\\t\\n\\t\\t\\t\\t\\t</se\'>, <Block Node: vpisOdhodka. Contents: [<TextNode: \'\\n\\t\\t\\t\\t\\n\\t\\t\\t\\t\'>]>, <TextNode: \'\\n\\t\\t\\t\\t\\n\\t\\t\\t\\t\'>, <Variable Node: warning>, <TextNode: \'\\n\\t\\t\\t\\t\\t\\t\\n\\t\\t\\t</div>\\t\\t\\n\\t\\t\\n\\t\\t\'>]>}]'
"GET /kalkulator/vpisiOdhodek.html HTTP/1.1" 200 2117
(0.001) SELECT "django_session"."session_key", "django_session"."session_data", "django_session"."expire_date" FROM "django_session" WHERE ("django_session"."expire_date" > '2017-01-05 19:37:28.894148' AND "django_session"."session_key" = 'u9txi8tulni35b6kgahgojrlgnedzvag'); args=('2017-01-05 19:37:28.894148', 'u9txi8tulni35b6kgahgojrlgnedzvag')
(0.000) SELECT "auth_user"."id", "auth_user"."password", "auth_user"."last_login", "auth_user"."is_superuser", "auth_user"."username", "auth_user"."first_name", "auth_user"."last_name", "auth_user"."email", "auth_user"."is_staff", "auth_user"."is_active", "auth_user"."date_joined" FROM "auth_user" WHERE "auth_user"."id" = 32; args=(32,)
(0.001) SELECT "kalkulator_racun"."id", "kalkulator_racun"."uporabnik_id", "kalkulator_racun"."ime", "kalkulator_racun"."stanje" FROM "kalkulator_racun"; args=()
(0.001) SELECT "auth_user"."id", "auth_user"."password", "auth_user"."last_login", "auth_user"."is_superuser", "auth_user"."username", "auth_user"."first_name", "auth_user"."last_name", "auth_user"."email", "auth_user"."is_staff", "auth_user"."is_active", "auth_user"."date_joined" FROM "auth_user" WHERE "auth_user"."id" = 32; args=(32,)
Exception while resolving variable 'warning' in template 'kalkulator/stanje.html'.
Traceback (most recent call last):
  File "C:\Program Files (x86)\Python35-32\lib\site-packages\django\template\base.py", line 885, in _resolve_lookup
    current = current[bit]
  File "C:\Program Files (x86)\Python35-32\lib\site-packages\django\template\context.py", line 75, in __getitem__
    raise KeyError(key)
KeyError: 'warning'

During handling of the above exception, another exception occurred:

Traceback (most recent call last):
  File "C:\Program Files (x86)\Python35-32\lib\site-packages\django\template\base.py", line 891, in _resolve_lookup
    if isinstance(current, BaseContext) and getattr(type(current), bit):
AttributeError: type object 'RequestContext' has no attribute 'warning'

During handling of the above exception, another exception occurred:

Traceback (most recent call last):
  File "C:\Program Files (x86)\Python35-32\lib\site-packages\django\template\base.py", line 900, in _resolve_lookup
    current = current[int(bit)]
ValueError: invalid literal for int() with base 10: 'warning'

During handling of the above exception, another exception occurred:

Traceback (most recent call last):
  File "C:\Program Files (x86)\Python35-32\lib\site-packages\django\template\base.py", line 907, in _resolve_lookup
    (bit, current))  # missing attribute
django.template.base.VariableDoesNotExist: Failed lookup for key [warning] in '[{\'None\': None, \'True\': True, \'False\': False}, {\'messages\': <django.contrib.messages.storage.fallback.FallbackStorage object at 0x03FEFA10>, \'csrf_token\': <SimpleLazyObject: \'6G5q084eOWhwD5k18B1g06ApauQlCaCkr1Pm8zRXDb1ZjiYtiZhtHM31aplq2aeU\'>, \'perms\': <django.contrib.auth.context_processors.PermWrapper object at 0x03FE3C90>, \'DEFAULT_MESSAGE_LEVELS\': {\'DEBUG\': 10, \'WARNING\': 30, \'INFO\': 20, \'ERROR\': 40, \'SUCCESS\': 25}, \'request\': <WSGIRequest: GET \'/kalkulator/stanje.html\'>, \'user\': <SimpleLazyObject: <User: goblinsly>>}, {}, {\'racuni\': <QuerySet [<Racun: goblinsly: Transakcijski Racun, 0.00€ >]>}, {\'block\': <Block Node: main. Contents: [<TextNode: \'\\n\\t<div id="Stanje"> \\n\\t\\t\\t\\n\'>, <django.template.defaulttags.CsrfTokenNode object at 0x03FE3110>, <TextNode: \' \\t\\t\\t\\t\\t\\t\\t\\t\\t\\t\\t\\n\\t\\t\\t<label>Pr\'>, <For Node: for racun in racuni, tail_len: 3>, <TextNode: \'\\t\\t\\t\\t\\t\\t\\t\\t\\t\\t\\t\\t\\t\\t\\t\\t\\t\\t\\t\\t\\t\\t\\n\\t\\t\'>, <Block Node: izpisStanja. Contents: [<TextNode: \'\\n\\t\\t\\t\'>]>, <TextNode: \'\\n\\t\\t\\t\\t\\t\\t\\t\\n\\t\\t\\t\'>, <Variable Node: warning>, <TextNode: \'\\t\\t\\t\\t\\t\\t\\t\\t\\n\\t\\t\\t\\t\\t\\n\\t\\t</div>\\t\\t\'>, <django.template.defaulttags.CsrfTokenNode object at 0x03FE3ED0>, <TextNode: \' \\t\\n\\t\\t\\t<label>Dodaj nov ra\'>, <django.template.defaulttags.CsrfTokenNode object at 0x03FE3730>, <TextNode: \' \\t\\t\\t\\t\\t\\t\\t\\t\\t\\t\\t\\n\\t\\t\\t<label>Iz\'>, <For Node: for racun in racuni, tail_len: 3>, <TextNode: \'\\t\\t\\t\\t\\t\\t\\t\\t\\t\\t\\t\\t\\t\\t\\t\\t\\t\\t\\t\\t\\t\\t\\n\\t\\t\'>]>}]'
"GET /kalkulator/stanje.html HTTP/1.1" 200 2662
(0.000) 
            SELECT name, type FROM sqlite_master
            WHERE type in ('table', 'view') AND NOT name='sqlite_sequence'
            ORDER BY name; args=None
(0.000) SELECT "django_migrations"."app", "django_migrations"."name" FROM "django_migrations"; args=()
(0.001) 
            SELECT name, type FROM sqlite_master
            WHERE type in ('table', 'view') AND NOT name='sqlite_sequence'
            ORDER BY name; args=None
(0.000) SELECT "django_migrations"."app", "django_migrations"."name" FROM "django_migrations"; args=()
(0.001) SELECT "django_session"."session_key", "django_session"."session_data", "django_session"."expire_date" FROM "django_session" WHERE ("django_session"."session_key" = 'u9txi8tulni35b6kgahgojrlgnedzvag' AND "django_session"."expire_date" > '2017-01-05 19:42:02.935364'); args=('u9txi8tulni35b6kgahgojrlgnedzvag', '2017-01-05 19:42:02.935364')
(0.000) SELECT "auth_user"."id", "auth_user"."password", "auth_user"."last_login", "auth_user"."is_superuser", "auth_user"."username", "auth_user"."first_name", "auth_user"."last_name", "auth_user"."email", "auth_user"."is_staff", "auth_user"."is_active", "auth_user"."date_joined" FROM "auth_user" WHERE "auth_user"."id" = 32; args=(32,)
(0.000) SELECT "kalkulator_racun"."id", "kalkulator_racun"."uporabnik_id", "kalkulator_racun"."ime", "kalkulator_racun"."stanje" FROM "kalkulator_racun"; args=()
(0.000) SELECT "auth_user"."id", "auth_user"."password", "auth_user"."last_login", "auth_user"."is_superuser", "auth_user"."username", "auth_user"."first_name", "auth_user"."last_name", "auth_user"."email", "auth_user"."is_staff", "auth_user"."is_active", "auth_user"."date_joined" FROM "auth_user" WHERE "auth_user"."id" = 32; args=(32,)
Exception while resolving variable 'warning' in template 'kalkulator/stanje.html'.
Traceback (most recent call last):
  File "C:\Program Files (x86)\Python35-32\lib\site-packages\django\template\base.py", line 885, in _resolve_lookup
    current = current[bit]
  File "C:\Program Files (x86)\Python35-32\lib\site-packages\django\template\context.py", line 75, in __getitem__
    raise KeyError(key)
KeyError: 'warning'

During handling of the above exception, another exception occurred:

Traceback (most recent call last):
  File "C:\Program Files (x86)\Python35-32\lib\site-packages\django\template\base.py", line 891, in _resolve_lookup
    if isinstance(current, BaseContext) and getattr(type(current), bit):
AttributeError: type object 'RequestContext' has no attribute 'warning'

During handling of the above exception, another exception occurred:

Traceback (most recent call last):
  File "C:\Program Files (x86)\Python35-32\lib\site-packages\django\template\base.py", line 900, in _resolve_lookup
    current = current[int(bit)]
ValueError: invalid literal for int() with base 10: 'warning'

During handling of the above exception, another exception occurred:

Traceback (most recent call last):
  File "C:\Program Files (x86)\Python35-32\lib\site-packages\django\template\base.py", line 907, in _resolve_lookup
    (bit, current))  # missing attribute
django.template.base.VariableDoesNotExist: Failed lookup for key [warning] in '[{\'True\': True, \'False\': False, \'None\': None}, {\'csrf_token\': <SimpleLazyObject: \'Nz7xccXJ7hHj57rwLcUc6AJRlINDXP4K8URtkDKsWwrMLk5YVAapNgctlDiInPGk\'>, \'DEFAULT_MESSAGE_LEVELS\': {\'SUCCESS\': 25, \'DEBUG\': 10, \'INFO\': 20, \'ERROR\': 40, \'WARNING\': 30}, \'user\': <SimpleLazyObject: <User: goblinsly>>, \'request\': <WSGIRequest: GET \'/kalkulator/stanje.html\'>, \'perms\': <django.contrib.auth.context_processors.PermWrapper object at 0x03EB7F10>, \'messages\': <django.contrib.messages.storage.fallback.FallbackStorage object at 0x03C02070>}, {}, {\'racuni\': <QuerySet [<Racun: goblinsly: Transakcijski Racun, 0.00€ >]>}, {\'block\': <Block Node: main. Contents: [<TextNode: \'\\n\\t<div id="Stanje"> \\n\\t\\t\\t\\n\'>, <django.template.defaulttags.CsrfTokenNode object at 0x03EB7290>, <TextNode: \' \\t\\t\\t\\t\\t\\t\\t\\t\\t\\t\\t\\n\\t\\t\\t<label>Pr\'>, <For Node: for racun in racuni, tail_len: 3>, <TextNode: \'\\t\\t\\t\\t\\t\\t\\t\\t\\t\\t\\t\\t\\t\\t\\t\\t\\t\\t\\t\\t\\t\\t\\n\\t\\t\'>, <Block Node: izpisStanja. Contents: [<TextNode: \'\\n\\t\\t\\t\'>]>, <TextNode: \'\\n\\t\\t\\t\\t\\t\\t\\t\\n\\t\\t\\t\'>, <Variable Node: warning>, <TextNode: \'\\t\\t\\t\\t\\t\\t\\t\\t\\n\\t\\t\\t\\t\\t\\n\\t\\t</div>\\t\\t\'>, <django.template.defaulttags.CsrfTokenNode object at 0x03C74C10>, <TextNode: \' \\t\\n\\t\\t\\t<label>Dodaj nov ra\'>, <django.template.defaulttags.CsrfTokenNode object at 0x03EB76F0>, <TextNode: \' \\t\\t\\t\\t\\t\\t\\t\\t\\t\\t\\t\\n\\t\\t\\t<label>Iz\'>, <For Node: for racun in racuni, tail_len: 3>, <TextNode: \'\\t\\t\\t\\t\\t\\t\\t\\t\\t\\t\\t\\t\\t\\t\\t\\t\\t\\t\\t\\t\\t\\t\\n\\t\\t\'>]>}]'
"GET /kalkulator/stanje.html HTTP/1.1" 200 2662
(0.001) SELECT "django_session"."session_key", "django_session"."session_data", "django_session"."expire_date" FROM "django_session" WHERE ("django_session"."session_key" = 'u9txi8tulni35b6kgahgojrlgnedzvag' AND "django_session"."expire_date" > '2017-01-05 19:42:03.594111'); args=('u9txi8tulni35b6kgahgojrlgnedzvag', '2017-01-05 19:42:03.594111')
(0.000) SELECT "auth_user"."id", "auth_user"."password", "auth_user"."last_login", "auth_user"."is_superuser", "auth_user"."username", "auth_user"."first_name", "auth_user"."last_name", "auth_user"."email", "auth_user"."is_staff", "auth_user"."is_active", "auth_user"."date_joined" FROM "auth_user" WHERE "auth_user"."id" = 32; args=(32,)
(0.001) SELECT "kalkulator_racun"."id", "kalkulator_racun"."uporabnik_id", "kalkulator_racun"."ime", "kalkulator_racun"."stanje" FROM "kalkulator_racun"; args=()
(0.001) SELECT "auth_user"."id", "auth_user"."password", "auth_user"."last_login", "auth_user"."is_superuser", "auth_user"."username", "auth_user"."first_name", "auth_user"."last_name", "auth_user"."email", "auth_user"."is_staff", "auth_user"."is_active", "auth_user"."date_joined" FROM "auth_user" WHERE "auth_user"."id" = 32; args=(32,)
Exception while resolving variable 'warning' in template 'kalkulator/vpisiPrihodek.html'.
Traceback (most recent call last):
  File "C:\Program Files (x86)\Python35-32\lib\site-packages\django\template\base.py", line 885, in _resolve_lookup
    current = current[bit]
  File "C:\Program Files (x86)\Python35-32\lib\site-packages\django\template\context.py", line 75, in __getitem__
    raise KeyError(key)
KeyError: 'warning'

During handling of the above exception, another exception occurred:

Traceback (most recent call last):
  File "C:\Program Files (x86)\Python35-32\lib\site-packages\django\template\base.py", line 891, in _resolve_lookup
    if isinstance(current, BaseContext) and getattr(type(current), bit):
AttributeError: type object 'RequestContext' has no attribute 'warning'

During handling of the above exception, another exception occurred:

Traceback (most recent call last):
  File "C:\Program Files (x86)\Python35-32\lib\site-packages\django\template\base.py", line 900, in _resolve_lookup
    current = current[int(bit)]
ValueError: invalid literal for int() with base 10: 'warning'

During handling of the above exception, another exception occurred:

Traceback (most recent call last):
  File "C:\Program Files (x86)\Python35-32\lib\site-packages\django\template\base.py", line 907, in _resolve_lookup
    (bit, current))  # missing attribute
django.template.base.VariableDoesNotExist: Failed lookup for key [warning] in '[{\'True\': True, \'False\': False, \'None\': None}, {\'csrf_token\': <SimpleLazyObject: \'aT4S7qabDRQNz1kuUmhsRxWZAEw57WysveOOfRXUs6AgfeYW4KxFydpBAz1axWa2\'>, \'DEFAULT_MESSAGE_LEVELS\': {\'SUCCESS\': 25, \'DEBUG\': 10, \'INFO\': 20, \'ERROR\': 40, \'WARNING\': 30}, \'user\': <SimpleLazyObject: <User: goblinsly>>, \'request\': <WSGIRequest: GET \'/kalkulator/vpisiPrihodek.html\'>, \'perms\': <django.contrib.auth.context_processors.PermWrapper object at 0x03EB7BF0>, \'messages\': <django.contrib.messages.storage.fallback.FallbackStorage object at 0x03EB75F0>}, {}, {\'racuni\': <QuerySet [<Racun: goblinsly: Transakcijski Racun, 0.00€ >]>}, {\'block\': <Block Node: main. Contents: [<TextNode: \'\\n\\n\\t<div id="Obrazec">\\n\\t\\t\\t\'>, <django.template.defaulttags.CsrfTokenNode object at 0x03EB7F10>, <TextNode: \' \\t\\n\\t\\t\\t\\t\\t\\t\\t\\t\\n\\t\\t\\t<label>Kat\'>, <For Node: for racun in racuni, tail_len: 3>, <TextNode: \'\\t\\t\\t\\t\\t\\t\\t\\t\\t\\t\\t\\t\\t\\t\\t\\t\\t\\t\\t\\t\\t\\t\\t\\t\\t\'>, <Block Node: vpisPrihodka. Contents: [<TextNode: \'\\t\\t\\n\\t\\t\'>]>, <TextNode: \'\\t\\n\\t\\t\\n\\t\\t\'>, <Variable Node: warning>, <TextNode: \'\\n\\t\\t\\n\\t</div>\\n\\t\\t\\t\\t\\t\\n\\t</div>\'>]>}]'
"GET /kalkulator/vpisiPrihodek.html HTTP/1.1" 200 2017
(0.000) SELECT "django_session"."session_key", "django_session"."session_data", "django_session"."expire_date" FROM "django_session" WHERE ("django_session"."session_key" = 'u9txi8tulni35b6kgahgojrlgnedzvag' AND "django_session"."expire_date" > '2017-01-05 19:42:04.152867'); args=('u9txi8tulni35b6kgahgojrlgnedzvag', '2017-01-05 19:42:04.152867')
(0.001) SELECT "auth_user"."id", "auth_user"."password", "auth_user"."last_login", "auth_user"."is_superuser", "auth_user"."username", "auth_user"."first_name", "auth_user"."last_name", "auth_user"."email", "auth_user"."is_staff", "auth_user"."is_active", "auth_user"."date_joined" FROM "auth_user" WHERE "auth_user"."id" = 32; args=(32,)
(0.000) SELECT "kalkulator_racun"."id", "kalkulator_racun"."uporabnik_id", "kalkulator_racun"."ime", "kalkulator_racun"."stanje" FROM "kalkulator_racun"; args=()
(0.000) SELECT "auth_user"."id", "auth_user"."password", "auth_user"."last_login", "auth_user"."is_superuser", "auth_user"."username", "auth_user"."first_name", "auth_user"."last_name", "auth_user"."email", "auth_user"."is_staff", "auth_user"."is_active", "auth_user"."date_joined" FROM "auth_user" WHERE "auth_user"."id" = 32; args=(32,)
Exception while resolving variable 'warning' in template 'kalkulator/vpisiOdhodek.html'.
Traceback (most recent call last):
  File "C:\Program Files (x86)\Python35-32\lib\site-packages\django\template\base.py", line 885, in _resolve_lookup
    current = current[bit]
  File "C:\Program Files (x86)\Python35-32\lib\site-packages\django\template\context.py", line 75, in __getitem__
    raise KeyError(key)
KeyError: 'warning'

During handling of the above exception, another exception occurred:

Traceback (most recent call last):
  File "C:\Program Files (x86)\Python35-32\lib\site-packages\django\template\base.py", line 891, in _resolve_lookup
    if isinstance(current, BaseContext) and getattr(type(current), bit):
AttributeError: type object 'RequestContext' has no attribute 'warning'

During handling of the above exception, another exception occurred:

Traceback (most recent call last):
  File "C:\Program Files (x86)\Python35-32\lib\site-packages\django\template\base.py", line 900, in _resolve_lookup
    current = current[int(bit)]
ValueError: invalid literal for int() with base 10: 'warning'

During handling of the above exception, another exception occurred:

Traceback (most recent call last):
  File "C:\Program Files (x86)\Python35-32\lib\site-packages\django\template\base.py", line 907, in _resolve_lookup
    (bit, current))  # missing attribute
django.template.base.VariableDoesNotExist: Failed lookup for key [warning] in '[{\'True\': True, \'False\': False, \'None\': None}, {\'csrf_token\': <SimpleLazyObject: \'t1gHVvaKI5XcdRxAgHp9TBiFPP7flEspOm0D3WXtxkHFT4b2q5FmAhLhPKCkLE4Z\'>, \'DEFAULT_MESSAGE_LEVELS\': {\'SUCCESS\': 25, \'DEBUG\': 10, \'INFO\': 20, \'ERROR\': 40, \'WARNING\': 30}, \'user\': <SimpleLazyObject: <User: goblinsly>>, \'request\': <WSGIRequest: GET \'/kalkulator/vpisiOdhodek.html\'>, \'perms\': <django.contrib.auth.context_processors.PermWrapper object at 0x03C74C50>, \'messages\': <django.contrib.messages.storage.fallback.FallbackStorage object at 0x03EB7250>}, {}, {\'racuni\': <QuerySet [<Racun: goblinsly: Transakcijski Racun, 0.00€ >]>}, {\'block\': <Block Node: main. Contents: [<TextNode: \'\\n\\t\\t\\t\\t\\n\\t\\t<div id="Obrazec"\'>, <django.template.defaulttags.CsrfTokenNode object at 0x03C74DF0>, <TextNode: \' \\t\\t\\t\\t\\t\\t\\t\\t\\t\\t\\t\\n\\t\\t\\t\\t\\t<label>\'>, <For Node: for racun in racuni, tail_len: 3>, <TextNode: \'\\t\\t\\t\\t\\t\\t\\t\\t\\t\\t\\t\\t\\t\\t\\t\\n\\t\\t\\t\\t\\t</se\'>, <Block Node: vpisOdhodka. Contents: [<TextNode: \'\\n\\t\\t\\t\\t\\n\\t\\t\\t\\t\'>]>, <TextNode: \'\\n\\t\\t\\t\\t\\n\\t\\t\\t\\t\'>, <Variable Node: warning>, <TextNode: \'\\n\\t\\t\\t\\t\\t\\t\\n\\t\\t\\t</div>\\t\\t\\n\\t\\t\\n\\t\\t\'>]>}]'
"GET /kalkulator/vpisiOdhodek.html HTTP/1.1" 200 2117
(0.001) SELECT "django_session"."session_key", "django_session"."session_data", "django_session"."expire_date" FROM "django_session" WHERE ("django_session"."session_key" = 'u9txi8tulni35b6kgahgojrlgnedzvag' AND "django_session"."expire_date" > '2017-01-05 19:42:04.713979'); args=('u9txi8tulni35b6kgahgojrlgnedzvag', '2017-01-05 19:42:04.713979')
(0.000) SELECT "auth_user"."id", "auth_user"."password", "auth_user"."last_login", "auth_user"."is_superuser", "auth_user"."username", "auth_user"."first_name", "auth_user"."last_name", "auth_user"."email", "auth_user"."is_staff", "auth_user"."is_active", "auth_user"."date_joined" FROM "auth_user" WHERE "auth_user"."id" = 32; args=(32,)
(0.000) SELECT "kalkulator_racun"."id", "kalkulator_racun"."uporabnik_id", "kalkulator_racun"."ime", "kalkulator_racun"."stanje" FROM "kalkulator_racun"; args=()
(0.000) SELECT "auth_user"."id", "auth_user"."password", "auth_user"."last_login", "auth_user"."is_superuser", "auth_user"."username", "auth_user"."first_name", "auth_user"."last_name", "auth_user"."email", "auth_user"."is_staff", "auth_user"."is_active", "auth_user"."date_joined" FROM "auth_user" WHERE "auth_user"."id" = 32; args=(32,)
Exception while resolving variable 'warning' in template 'kalkulator/porocila.html'.
Traceback (most recent call last):
  File "C:\Program Files (x86)\Python35-32\lib\site-packages\django\template\base.py", line 885, in _resolve_lookup
    current = current[bit]
  File "C:\Program Files (x86)\Python35-32\lib\site-packages\django\template\context.py", line 75, in __getitem__
    raise KeyError(key)
KeyError: 'warning'

During handling of the above exception, another exception occurred:

Traceback (most recent call last):
  File "C:\Program Files (x86)\Python35-32\lib\site-packages\django\template\base.py", line 891, in _resolve_lookup
    if isinstance(current, BaseContext) and getattr(type(current), bit):
AttributeError: type object 'RequestContext' has no attribute 'warning'

During handling of the above exception, another exception occurred:

Traceback (most recent call last):
  File "C:\Program Files (x86)\Python35-32\lib\site-packages\django\template\base.py", line 900, in _resolve_lookup
    current = current[int(bit)]
ValueError: invalid literal for int() with base 10: 'warning'

During handling of the above exception, another exception occurred:

Traceback (most recent call last):
  File "C:\Program Files (x86)\Python35-32\lib\site-packages\django\template\base.py", line 907, in _resolve_lookup
    (bit, current))  # missing attribute
django.template.base.VariableDoesNotExist: Failed lookup for key [warning] in '[{\'True\': True, \'False\': False, \'None\': None}, {\'csrf_token\': <SimpleLazyObject: <function csrf.<locals>._get_val at 0x03EFBD68>>, \'DEFAULT_MESSAGE_LEVELS\': {\'SUCCESS\': 25, \'DEBUG\': 10, \'INFO\': 20, \'ERROR\': 40, \'WARNING\': 30}, \'user\': <SimpleLazyObject: <User: goblinsly>>, \'request\': <WSGIRequest: GET \'/kalkulator/porocila.html\'>, \'perms\': <django.contrib.auth.context_processors.PermWrapper object at 0x03C74DB0>, \'messages\': <django.contrib.messages.storage.fallback.FallbackStorage object at 0x03C74F70>}, {}, {\'racuni\': <QuerySet [<Racun: goblinsly: Transakcijski Racun, 0.00€ >]>}, {\'block\': <Block Node: main. Contents: [<TextNode: \'\\n\\t<div id="Porocilo"> \\n\\t\\n\'>, <For Node: for racun in racuni, tail_len: 3>, <TextNode: \'\\t\\t\\t\\t\\t\\t\\t\\t\\t\\t\\t\\t\\t\\t\\t\\t\\t\\t\\t\\t\\t\\t\\n\\t\\t\'>, <Block Node: izpisStanja. Contents: [<TextNode: \'\\n\\t\\t\\t\\n\\t\\t\\t\'>]>, <TextNode: \'\\n\\t\\t\\t\\n\\t\\t\\t\'>, <Variable Node: warning>, <TextNode: \'\\n\\t\\t\\t\\n\\t\\t</div>\\t\\n\\t\\t\\n\\t</div>\'>]>}]'
"GET /kalkulator/porocila.html HTTP/1.1" 200 1798
(0.001) SELECT "django_session"."session_key", "django_session"."session_data", "django_session"."expire_date" FROM "django_session" WHERE ("django_session"."session_key" = 'u9txi8tulni35b6kgahgojrlgnedzvag' AND "django_session"."expire_date" > '2017-01-05 19:42:05.296531'); args=('u9txi8tulni35b6kgahgojrlgnedzvag', '2017-01-05 19:42:05.296531')
(0.000) SELECT "auth_user"."id", "auth_user"."password", "auth_user"."last_login", "auth_user"."is_superuser", "auth_user"."username", "auth_user"."first_name", "auth_user"."last_name", "auth_user"."email", "auth_user"."is_staff", "auth_user"."is_active", "auth_user"."date_joined" FROM "auth_user" WHERE "auth_user"."id" = 32; args=(32,)
(0.000) SELECT "kalkulator_racun"."id", "kalkulator_racun"."uporabnik_id", "kalkulator_racun"."ime", "kalkulator_racun"."stanje" FROM "kalkulator_racun"; args=()
(0.000) SELECT "auth_user"."id", "auth_user"."password", "auth_user"."last_login", "auth_user"."is_superuser", "auth_user"."username", "auth_user"."first_name", "auth_user"."last_name", "auth_user"."email", "auth_user"."is_staff", "auth_user"."is_active", "auth_user"."date_joined" FROM "auth_user" WHERE "auth_user"."id" = 32; args=(32,)
Exception while resolving variable 'warning' in template 'kalkulator/vpisiOdhodek.html'.
Traceback (most recent call last):
  File "C:\Program Files (x86)\Python35-32\lib\site-packages\django\template\base.py", line 885, in _resolve_lookup
    current = current[bit]
  File "C:\Program Files (x86)\Python35-32\lib\site-packages\django\template\context.py", line 75, in __getitem__
    raise KeyError(key)
KeyError: 'warning'

During handling of the above exception, another exception occurred:

Traceback (most recent call last):
  File "C:\Program Files (x86)\Python35-32\lib\site-packages\django\template\base.py", line 891, in _resolve_lookup
    if isinstance(current, BaseContext) and getattr(type(current), bit):
AttributeError: type object 'RequestContext' has no attribute 'warning'

During handling of the above exception, another exception occurred:

Traceback (most recent call last):
  File "C:\Program Files (x86)\Python35-32\lib\site-packages\django\template\base.py", line 900, in _resolve_lookup
    current = current[int(bit)]
ValueError: invalid literal for int() with base 10: 'warning'

During handling of the above exception, another exception occurred:

Traceback (most recent call last):
  File "C:\Program Files (x86)\Python35-32\lib\site-packages\django\template\base.py", line 907, in _resolve_lookup
    (bit, current))  # missing attribute
django.template.base.VariableDoesNotExist: Failed lookup for key [warning] in '[{\'True\': True, \'False\': False, \'None\': None}, {\'csrf_token\': <SimpleLazyObject: \'EDRvKF7HKiNYPowaWmiGAzOCLu66ZiRtZYBrS6UqzxxrvBaC6KyThfheLpBbpit3\'>, \'DEFAULT_MESSAGE_LEVELS\': {\'SUCCESS\': 25, \'DEBUG\': 10, \'INFO\': 20, \'ERROR\': 40, \'WARNING\': 30}, \'user\': <SimpleLazyObject: <User: goblinsly>>, \'request\': <WSGIRequest: GET \'/kalkulator/vpisiOdhodek.html\'>, \'perms\': <django.contrib.auth.context_processors.PermWrapper object at 0x03EBF4D0>, \'messages\': <django.contrib.messages.storage.fallback.FallbackStorage object at 0x03C74E30>}, {}, {\'racuni\': <QuerySet [<Racun: goblinsly: Transakcijski Racun, 0.00€ >]>}, {\'block\': <Block Node: main. Contents: [<TextNode: \'\\n\\t\\t\\t\\t\\n\\t\\t<div id="Obrazec"\'>, <django.template.defaulttags.CsrfTokenNode object at 0x03EBF990>, <TextNode: \' \\t\\t\\t\\t\\t\\t\\t\\t\\t\\t\\t\\n\\t\\t\\t\\t\\t<label>\'>, <For Node: for racun in racuni, tail_len: 3>, <TextNode: \'\\t\\t\\t\\t\\t\\t\\t\\t\\t\\t\\t\\t\\t\\t\\t\\n\\t\\t\\t\\t\\t</se\'>, <Block Node: vpisOdhodka. Contents: [<TextNode: \'\\n\\t\\t\\t\\t\\n\\t\\t\\t\\t\'>]>, <TextNode: \'\\n\\t\\t\\t\\t\\n\\t\\t\\t\\t\'>, <Variable Node: warning>, <TextNode: \'\\n\\t\\t\\t\\t\\t\\t\\n\\t\\t\\t</div>\\t\\t\\n\\t\\t\\n\\t\\t\'>]>}]'
"GET /kalkulator/vpisiOdhodek.html HTTP/1.1" 200 2117
(0.001) SELECT "django_session"."session_key", "django_session"."session_data", "django_session"."expire_date" FROM "django_session" WHERE ("django_session"."session_key" = 'u9txi8tulni35b6kgahgojrlgnedzvag' AND "django_session"."expire_date" > '2017-01-05 19:42:06.001316'); args=('u9txi8tulni35b6kgahgojrlgnedzvag', '2017-01-05 19:42:06.001316')
(0.000) SELECT "auth_user"."id", "auth_user"."password", "auth_user"."last_login", "auth_user"."is_superuser", "auth_user"."username", "auth_user"."first_name", "auth_user"."last_name", "auth_user"."email", "auth_user"."is_staff", "auth_user"."is_active", "auth_user"."date_joined" FROM "auth_user" WHERE "auth_user"."id" = 32; args=(32,)
(0.000) SELECT "kalkulator_racun"."id", "kalkulator_racun"."uporabnik_id", "kalkulator_racun"."ime", "kalkulator_racun"."stanje" FROM "kalkulator_racun"; args=()
(0.000) SELECT "auth_user"."id", "auth_user"."password", "auth_user"."last_login", "auth_user"."is_superuser", "auth_user"."username", "auth_user"."first_name", "auth_user"."last_name", "auth_user"."email", "auth_user"."is_staff", "auth_user"."is_active", "auth_user"."date_joined" FROM "auth_user" WHERE "auth_user"."id" = 32; args=(32,)
Exception while resolving variable 'warning' in template 'kalkulator/vpisiPrihodek.html'.
Traceback (most recent call last):
  File "C:\Program Files (x86)\Python35-32\lib\site-packages\django\template\base.py", line 885, in _resolve_lookup
    current = current[bit]
  File "C:\Program Files (x86)\Python35-32\lib\site-packages\django\template\context.py", line 75, in __getitem__
    raise KeyError(key)
KeyError: 'warning'

During handling of the above exception, another exception occurred:

Traceback (most recent call last):
  File "C:\Program Files (x86)\Python35-32\lib\site-packages\django\template\base.py", line 891, in _resolve_lookup
    if isinstance(current, BaseContext) and getattr(type(current), bit):
AttributeError: type object 'RequestContext' has no attribute 'warning'

During handling of the above exception, another exception occurred:

Traceback (most recent call last):
  File "C:\Program Files (x86)\Python35-32\lib\site-packages\django\template\base.py", line 900, in _resolve_lookup
    current = current[int(bit)]
ValueError: invalid literal for int() with base 10: 'warning'

During handling of the above exception, another exception occurred:

Traceback (most recent call last):
  File "C:\Program Files (x86)\Python35-32\lib\site-packages\django\template\base.py", line 907, in _resolve_lookup
    (bit, current))  # missing attribute
django.template.base.VariableDoesNotExist: Failed lookup for key [warning] in '[{\'True\': True, \'False\': False, \'None\': None}, {\'csrf_token\': <SimpleLazyObject: \'2MBLnpvY1Ey2FVo34SsASC1xZtrwHHJ5n7lHvQiHQTivl82vegINziu9ZoWB7HlF\'>, \'DEFAULT_MESSAGE_LEVELS\': {\'SUCCESS\': 25, \'DEBUG\': 10, \'INFO\': 20, \'ERROR\': 40, \'WARNING\': 30}, \'user\': <SimpleLazyObject: <User: goblinsly>>, \'request\': <WSGIRequest: GET \'/kalkulator/vpisiPrihodek.html\'>, \'perms\': <django.contrib.auth.context_processors.PermWrapper object at 0x03EBF330>, \'messages\': <django.contrib.messages.storage.fallback.FallbackStorage object at 0x03EBFD30>}, {}, {\'racuni\': <QuerySet [<Racun: goblinsly: Transakcijski Racun, 0.00€ >]>}, {\'block\': <Block Node: main. Contents: [<TextNode: \'\\n\\n\\t<div id="Obrazec">\\n\\t\\t\\t\'>, <django.template.defaulttags.CsrfTokenNode object at 0x03EB7570>, <TextNode: \' \\t\\n\\t\\t\\t\\t\\t\\t\\t\\t\\n\\t\\t\\t<label>Kat\'>, <For Node: for racun in racuni, tail_len: 3>, <TextNode: \'\\t\\t\\t\\t\\t\\t\\t\\t\\t\\t\\t\\t\\t\\t\\t\\t\\t\\t\\t\\t\\t\\t\\t\\t\\t\'>, <Block Node: vpisPrihodka. Contents: [<TextNode: \'\\t\\t\\n\\t\\t\'>]>, <TextNode: \'\\t\\n\\t\\t\\n\\t\\t\'>, <Variable Node: warning>, <TextNode: \'\\n\\t\\t\\n\\t</div>\\n\\t\\t\\t\\t\\t\\n\\t</div>\'>]>}]'
"GET /kalkulator/vpisiPrihodek.html HTTP/1.1" 200 2017
(0.000) SELECT "django_session"."session_key", "django_session"."session_data", "django_session"."expire_date" FROM "django_session" WHERE ("django_session"."session_key" = 'u9txi8tulni35b6kgahgojrlgnedzvag' AND "django_session"."expire_date" > '2017-01-05 19:42:06.439660'); args=('u9txi8tulni35b6kgahgojrlgnedzvag', '2017-01-05 19:42:06.439660')
(0.001) SELECT "auth_user"."id", "auth_user"."password", "auth_user"."last_login", "auth_user"."is_superuser", "auth_user"."username", "auth_user"."first_name", "auth_user"."last_name", "auth_user"."email", "auth_user"."is_staff", "auth_user"."is_active", "auth_user"."date_joined" FROM "auth_user" WHERE "auth_user"."id" = 32; args=(32,)
(0.000) SELECT "kalkulator_racun"."id", "kalkulator_racun"."uporabnik_id", "kalkulator_racun"."ime", "kalkulator_racun"."stanje" FROM "kalkulator_racun"; args=()
(0.000) SELECT "auth_user"."id", "auth_user"."password", "auth_user"."last_login", "auth_user"."is_superuser", "auth_user"."username", "auth_user"."first_name", "auth_user"."last_name", "auth_user"."email", "auth_user"."is_staff", "auth_user"."is_active", "auth_user"."date_joined" FROM "auth_user" WHERE "auth_user"."id" = 32; args=(32,)
Exception while resolving variable 'warning' in template 'kalkulator/stanje.html'.
Traceback (most recent call last):
  File "C:\Program Files (x86)\Python35-32\lib\site-packages\django\template\base.py", line 885, in _resolve_lookup
    current = current[bit]
  File "C:\Program Files (x86)\Python35-32\lib\site-packages\django\template\context.py", line 75, in __getitem__
    raise KeyError(key)
KeyError: 'warning'

During handling of the above exception, another exception occurred:

Traceback (most recent call last):
  File "C:\Program Files (x86)\Python35-32\lib\site-packages\django\template\base.py", line 891, in _resolve_lookup
    if isinstance(current, BaseContext) and getattr(type(current), bit):
AttributeError: type object 'RequestContext' has no attribute 'warning'

During handling of the above exception, another exception occurred:

Traceback (most recent call last):
  File "C:\Program Files (x86)\Python35-32\lib\site-packages\django\template\base.py", line 900, in _resolve_lookup
    current = current[int(bit)]
ValueError: invalid literal for int() with base 10: 'warning'

During handling of the above exception, another exception occurred:

Traceback (most recent call last):
  File "C:\Program Files (x86)\Python35-32\lib\site-packages\django\template\base.py", line 907, in _resolve_lookup
    (bit, current))  # missing attribute
django.template.base.VariableDoesNotExist: Failed lookup for key [warning] in '[{\'True\': True, \'False\': False, \'None\': None}, {\'csrf_token\': <SimpleLazyObject: \'7JZdmt6N3GYlOtcsZlg5p59KVeSSx26Rs4J9uUTwSVIOuGQU9Jwi6LCmV9nXX2Ir\'>, \'DEFAULT_MESSAGE_LEVELS\': {\'SUCCESS\': 25, \'DEBUG\': 10, \'INFO\': 20, \'ERROR\': 40, \'WARNING\': 30}, \'user\': <SimpleLazyObject: <User: goblinsly>>, \'request\': <WSGIRequest: GET \'/kalkulator/stanje.html\'>, \'perms\': <django.contrib.auth.context_processors.PermWrapper object at 0x03EB71B0>, \'messages\': <django.contrib.messages.storage.fallback.FallbackStorage object at 0x03EBFB10>}, {}, {\'racuni\': <QuerySet [<Racun: goblinsly: Transakcijski Racun, 0.00€ >]>}, {\'block\': <Block Node: main. Contents: [<TextNode: \'\\n\\t<div id="Stanje"> \\n\\t\\t\\t\\n\'>, <django.template.defaulttags.CsrfTokenNode object at 0x03EB7650>, <TextNode: \' \\t\\t\\t\\t\\t\\t\\t\\t\\t\\t\\t\\n\\t\\t\\t<label>Pr\'>, <For Node: for racun in racuni, tail_len: 3>, <TextNode: \'\\t\\t\\t\\t\\t\\t\\t\\t\\t\\t\\t\\t\\t\\t\\t\\t\\t\\t\\t\\t\\t\\t\\n\\t\\t\'>, <Block Node: izpisStanja. Contents: [<TextNode: \'\\n\\t\\t\\t\'>]>, <TextNode: \'\\n\\t\\t\\t\\t\\t\\t\\t\\n\\t\\t\\t\'>, <Variable Node: warning>, <TextNode: \'\\t\\t\\t\\t\\t\\t\\t\\t\\n\\t\\t\\t\\t\\t\\n\\t\\t</div>\\t\\t\'>, <django.template.defaulttags.CsrfTokenNode object at 0x03EB7970>, <TextNode: \' \\t\\n\\t\\t\\t<label>Dodaj nov ra\'>, <django.template.defaulttags.CsrfTokenNode object at 0x03EDEB90>, <TextNode: \' \\t\\t\\t\\t\\t\\t\\t\\t\\t\\t\\t\\n\\t\\t\\t<label>Iz\'>, <For Node: for racun in racuni, tail_len: 3>, <TextNode: \'\\t\\t\\t\\t\\t\\t\\t\\t\\t\\t\\t\\t\\t\\t\\t\\t\\t\\t\\t\\t\\t\\t\\n\\t\\t\'>]>}]'
"GET /kalkulator/stanje.html HTTP/1.1" 200 2662
(0.001) 
            SELECT name, type FROM sqlite_master
            WHERE type in ('table', 'view') AND NOT name='sqlite_sequence'
            ORDER BY name; args=None
(0.001) SELECT "django_migrations"."app", "django_migrations"."name" FROM "django_migrations"; args=()
(0.001) SELECT "django_session"."session_key", "django_session"."session_data", "django_session"."expire_date" FROM "django_session" WHERE ("django_session"."expire_date" > '2017-01-05 19:44:53.970193' AND "django_session"."session_key" = 'u9txi8tulni35b6kgahgojrlgnedzvag'); args=('2017-01-05 19:44:53.970193', 'u9txi8tulni35b6kgahgojrlgnedzvag')
(0.000) SELECT "auth_user"."id", "auth_user"."password", "auth_user"."last_login", "auth_user"."is_superuser", "auth_user"."username", "auth_user"."first_name", "auth_user"."last_name", "auth_user"."email", "auth_user"."is_staff", "auth_user"."is_active", "auth_user"."date_joined" FROM "auth_user" WHERE "auth_user"."id" = 32; args=(32,)
(0.001) SELECT "kalkulator_racun"."id", "kalkulator_racun"."uporabnik_id", "kalkulator_racun"."ime", "kalkulator_racun"."stanje" FROM "kalkulator_racun"; args=()
(0.000) SELECT "auth_user"."id", "auth_user"."password", "auth_user"."last_login", "auth_user"."is_superuser", "auth_user"."username", "auth_user"."first_name", "auth_user"."last_name", "auth_user"."email", "auth_user"."is_staff", "auth_user"."is_active", "auth_user"."date_joined" FROM "auth_user" WHERE "auth_user"."id" = 32; args=(32,)
Exception while resolving variable 'warning' in template 'kalkulator/stanje.html'.
Traceback (most recent call last):
  File "C:\Program Files (x86)\Python35-32\lib\site-packages\django\template\base.py", line 885, in _resolve_lookup
    current = current[bit]
  File "C:\Program Files (x86)\Python35-32\lib\site-packages\django\template\context.py", line 75, in __getitem__
    raise KeyError(key)
KeyError: 'warning'

During handling of the above exception, another exception occurred:

Traceback (most recent call last):
  File "C:\Program Files (x86)\Python35-32\lib\site-packages\django\template\base.py", line 891, in _resolve_lookup
    if isinstance(current, BaseContext) and getattr(type(current), bit):
AttributeError: type object 'RequestContext' has no attribute 'warning'

During handling of the above exception, another exception occurred:

Traceback (most recent call last):
  File "C:\Program Files (x86)\Python35-32\lib\site-packages\django\template\base.py", line 900, in _resolve_lookup
    current = current[int(bit)]
ValueError: invalid literal for int() with base 10: 'warning'

During handling of the above exception, another exception occurred:

Traceback (most recent call last):
  File "C:\Program Files (x86)\Python35-32\lib\site-packages\django\template\base.py", line 907, in _resolve_lookup
    (bit, current))  # missing attribute
django.template.base.VariableDoesNotExist: Failed lookup for key [warning] in '[{\'True\': True, \'False\': False, \'None\': None}, {\'request\': <WSGIRequest: GET \'/kalkulator/stanje.html\'>, \'user\': <SimpleLazyObject: <User: goblinsly>>, \'DEFAULT_MESSAGE_LEVELS\': {\'WARNING\': 30, \'ERROR\': 40, \'SUCCESS\': 25, \'INFO\': 20, \'DEBUG\': 10}, \'perms\': <django.contrib.auth.context_processors.PermWrapper object at 0x04469F30>, \'messages\': <django.contrib.messages.storage.fallback.FallbackStorage object at 0x0418DE90>, \'csrf_token\': <SimpleLazyObject: \'A2evftFIw0F2YXSozY2hDv3OHJsr3RVZVnYrnUsrlfpvEawQJmiukbwqHEXwtRxz\'>}, {}, {\'racuni\': <QuerySet [<Racun: goblinsly: Transakcijski Racun, 0.00€ >]>}, {\'block\': <Block Node: main. Contents: [<TextNode: \'\\n\\t<div id="Stanje"> \\n\\t\\t\\t\\n\'>, <django.template.defaulttags.CsrfTokenNode object at 0x044692B0>, <TextNode: \' \\t\\t\\t\\t\\t\\t\\t\\t\\t\\t\\t\\n\\t\\t\\t<label>Pr\'>, <For Node: for racun in racuni, tail_len: 3>, <TextNode: \'\\t\\t\\t\\t\\t\\t\\t\\t\\t\\t\\t\\t\\t\\t\\t\\t\\t\\t\\t\\t\\t\\t\\n\\t\\t\'>, <Block Node: izpisStanja. Contents: [<TextNode: \'\\n\\t\\t\\t\'>]>, <TextNode: \'\\n\\t\\t\\t\\t\\t\\t\\t\\n\\t\\t\\t\'>, <Variable Node: warning>, <TextNode: \'\\t\\t\\t\\t\\t\\t\\t\\t\\n\\t\\t\\t\\t\\t\\n\\t\\t</div>\\t\\t\'>, <django.template.defaulttags.CsrfTokenNode object at 0x04223C30>, <TextNode: \' \\t\\n\\t\\t\\t<label>Dodaj nov ra\'>, <django.template.defaulttags.CsrfTokenNode object at 0x04469710>, <TextNode: \' \\t\\t\\t\\t\\t\\t\\t\\t\\t\\t\\t\\n\\t\\t\\t<label>Iz\'>, <For Node: for racun in racuni, tail_len: 3>, <TextNode: \'\\t\\t\\t\\t\\t\\t\\t\\t\\t\\t\\t\\t\\t\\t\\t\\t\\t\\t\\t\\t\\t\\t\\n\\t\\t\'>]>}]'
"GET /kalkulator/stanje.html HTTP/1.1" 200 2662
(0.001) SELECT "django_session"."session_key", "django_session"."session_data", "django_session"."expire_date" FROM "django_session" WHERE ("django_session"."expire_date" > '2017-01-05 19:44:54.782889' AND "django_session"."session_key" = 'u9txi8tulni35b6kgahgojrlgnedzvag'); args=('2017-01-05 19:44:54.782889', 'u9txi8tulni35b6kgahgojrlgnedzvag')
(0.000) SELECT "auth_user"."id", "auth_user"."password", "auth_user"."last_login", "auth_user"."is_superuser", "auth_user"."username", "auth_user"."first_name", "auth_user"."last_name", "auth_user"."email", "auth_user"."is_staff", "auth_user"."is_active", "auth_user"."date_joined" FROM "auth_user" WHERE "auth_user"."id" = 32; args=(32,)
(0.000) SELECT "django_session"."session_key", "django_session"."session_data", "django_session"."expire_date" FROM "django_session" WHERE "django_session"."session_key" = 'u9txi8tulni35b6kgahgojrlgnedzvag'; args=('u9txi8tulni35b6kgahgojrlgnedzvag',)
(0.000) BEGIN; args=None
(0.000) DELETE FROM "django_session" WHERE "django_session"."session_key" IN ('u9txi8tulni35b6kgahgojrlgnedzvag'); args=('u9txi8tulni35b6kgahgojrlgnedzvag',)
"GET /kalkulator/logout/ HTTP/1.1" 302 0
"GET /kalkulator/ HTTP/1.1" 200 1087
